Workbook
Name _413565: "hdong+Sheet1!$A$2:$J$24263!$A$13374"
Name _o1: [1]概要!$B$18
Name _o2: [1]概要!$B$19
Name _oa: [2]概要!$B$20
Name _ob: [2]概要!$B$21
Name _q1: [1]概要!$D$18
Name _q2: [1]概要!$D$19
Name app_names: [3]Applications!$A$5:$A$10
Name asc: SUM(#REF!)
Name asc: SUM(#REF!)
Name asc: SUM(#REF!)
Name asc: SUM(#REF!)
Name asc: SUM(#REF!)
Name BL: "$A$1:$f$11"
Name CLVC3: 0.1
Name colum: 1
Name css_mode: '[4]Prerequisites '!$C$81:$C$83
Name CSS_MTU: '[4]Prerequisites '!$C$75:$C$79
Name Device_Function: '[5]Lookup-Naming'!$L$5:$L$14
Name Device_Model: '[5]Lookup-Naming'!$O$5:$O$15
Name Document_array: {"Book1"}
Name Document_array: {"Book1"}
Name Document_array: {"Book1"}
Name Document_array: {"Book1"}
Name Domain_Name: '[5]Lookup-Naming'!$F$5
Name Drawpoints: 1
Name DSTD_Clear: #N/A
Name Environment_Name: '[5]Lookup-Naming'!$I$5:$I$7
Name Heä_soá_laép_xaø_H: 1.7
Name HSCT3: 0.1
Name HSDN: 2.5
Name HSLXH: 1.7
Name HTML1_10: ""
Name HTML1_11: 1
Name HTML1_12: "C:\WINDOWS\DESKTOP\dallas.htm"
Name HTML1_2: 1
Name HTML1_3: "BSC-MTX Equipment"
Name HTML1_4: "Materials List - Dallas Switch"
Name HTML1_5: ""
Name HTML1_6: 1
Name HTML1_7: 1
Name HTML1_8: "2/10/97"
Name HTML1_9: "Nortel - CDMA Network Planning"
Name HTML2_10: ""
Name HTML2_11: 1
Name HTML2_12: "C:\WINDOWS\DESKTOP\dallas.htm"
Name HTML2_2: 1
Name HTML2_3: "BSC-MTX Tool 4"
Name HTML2_4: "Materials List"
Name HTML2_5: ""
Name HTML2_6: -4146
Name HTML2_7: -4146
Name HTML2_8: "2/10/97"
Name HTML2_9: "Nortel"
Name HTML3_10: ""
Name HTML3_11: 1
Name HTML3_12: "C:\WINDOWS\DESKTOP\MyHTML.htm"
Name HTML3_2: 1
Name HTML3_3: "BSC-MTX Tool 4"
Name HTML3_4: "Materials List"

Sheet MME_Lic
P1: =O14/L14*L15 -> 2424.2424 | Q1: =P14/M14*M15 -> 4000
A3: Node | B3: Node | C3: Existing | F3: Targeted (Q4-2021) | I3: Targeted (Q4-2023) | L3: Targeted (Q4-2024) | O3: License VHKT | Q3: Current kSAU 10/2024 | S3: SGSN/MME Pool | T3: Vendor | U3: Telco-Cloud | V3: PE-PS | W3: Note
C4: KSAU | D4: KBearer | E4: KPPS | F4: KSAU | G4: KBearer | H4: KPPS | I4: KSAU | J4: KBearer | K4: KPPS | L4: KSAU | M4: KBearer | N4: KPPS | O4: KSAU | P4: KBearer | Q4: KSAU | R4: KBearer | Z4: KV | AA4: SGSN/MME Pool | AB4: PE-PS | AC4: TC/Native | AD4: License kSAU commercial | AF4: License kSAU VHKT | AH4: Current kSAU 10/2024 | AI4: Phân bổ current kSAU 10/2024 | AJ4: % SAU/License (1 TC down) | AK4: % SAU/License VHKT (1 TC down) | AL4: TC down
A5: =LEFT(B5,6) -> SGHL04 | B5: SGHL04 (MKVIII) | C5: 2500 | D5: 2300 | E5: 28 | F5: 2500 | G5: 2300 | H5: 28 | I5: 2500 | J5: 2300 | K5: 28 | L5: 2500 | M5: 2300 | N5: 28 | O5: 2500 | P5: 5000 | Q5: 2341.017 | R5: 3037.923 | S5: HNI01 | T5: Native Ericsson | U5: Native01 | V5: PEPS_HLC_03/04 | X5: =LEFT(B5,6) -> SGHL04 | Z5: KV1 | AA5: HNI01 (Eric) | AB5: PEDĐ_HLC_05/06 | AC5: Native01 | AD5: =SUMIF($U$5:$V$48,AC5,$L$5:$L$48) -> 18200 | AE5: =AD5+AD6+AD7 -> 35400 | AF5: =SUMIF($U$5:$V$48,AC5,$O$5:$O$48) -> 21000 | AG5: =AF5+AF6+AF7 -> 41800 | AH5: =SUMIF($U$5:$V$48,AC5,$Q$5:$Q$48) -> 18129.374 | AI5: =24500 -> 24500 | AJ5: =$AI5/(AE5-AD6) -> 0.9141791 | AK5: =$AI5/(AG5-AF6) -> 0.78025478
A6: =LEFT(B6,6) -> SGHL05 | B6: SGHL05 (MKVIII) | C6: 2500 | D6: 2300 | E6: 28 | F6: 2500 | G6: 2300 | H6: 28 | I6: 2500 | J6: 2300 | K6: 28 | L6: 2500 | M6: 2300 | N6: 28 | O6: 2500 | P6: 5000 | Q6: 2411.403 | R6: 3155.254 | T6: Native Ericsson | U6: Native01 | V6: PEPS_HLC_03/04 | X6: =LEFT(B6,6) -> SGHL05 | AB6: PEPS_HLC_05/06 | AC6: TCHL01 | AD6: =SUMIF($U$5:$V$48,AC6,$L$5:$L$48) -> 8600 | AF6: =SUMIF($U$5:$V$48,AC6,$O$5:$O$48) -> 10400 | AH6: =SUMIF($U$5:$V$48,AC6,$Q$5:$Q$48) -> 5788.734
A7: =LEFT(B7,6) -> SGHL06 | B7: SGHL06 (MKX) | C7: 3300 | D7: 3200 | E7: 31 | F7: 3300 | G7: 3200 | H7: 31 | I7: 3300 | J7: 3200 | K7: 31 | L7: 3300 | M7: 3200 | N7: 31 | O7: 4000 | P7: 6600 | Q7: 2708.021 | R7: 3699.915 | T7: Native Ericsson | U7: Native01 | V7: PEDĐ_HLC_05/06 | X7: =LEFT(B7,6) -> SGHL06 | AB7: PEPS_HLC_05/06 | AC7: TCHL02 | AD7: =SUMIF($U$5:$V$48,AC7,$L$5:$L$48) -> 8600 | AF7: =SUMIF($U$5:$V$48,AC7,$O$5:$O$48) -> 10400 | AH7: =SUMIF($U$5:$V$48,AC7,$Q$5:$Q$48) -> 6029.241 | AL7: down
A8: =LEFT(B8,6) -> SGHL07 | B8: SGHL07 (MKX) | C8: 3300 | D8: 3200 | E8: 31 | F8: 3300 | G8: 3200 | H8: 31 | I8: 3300 | J8: 3200 | K8: 31 | L8: 3300 | M8: 3200 | N8: 31 | O8: 4000 | P8: 6600 | Q8: 3410.305 | R8: 4514.249 | T8: Native Ericsson | U8: Native01 | V8: PEDĐ_HLC_05/06 | X8: =LEFT(B8,6) -> SGHL07 | AA8: HNI02 (Eric) | AB8: PEPS_HLC_07/08 | AC8: TCHL04 | AD8: =SUMIF($U$5:$V$48,AC8,$L$5:$L$48) -> 6000 | AE8: =AD8+AD9 -> 12000 | AF8: =SUMIF($U$5:$V$48,AC8,$O$5:$O$48) -> 7200 | AG8: =AF8+AF9 -> 14400 | AH8: =SUMIF($U$5:$V$48,AC8,$Q$5:$Q$48) -> 0 | AI8: =SUM(AH5:AH9)-AI5 -> 5447.349 | AJ8: =AI8/(AE8-AD8) -> 0.9078915 | AK8: =AI8/(AG8-AF9) -> 0.75657625
A9: =LEFT(B9,6) -> SGHL08 | B9: SGHL08 (MKX) | C9: 3300 | D9: 3200 | E9: 31 | F9: 3300 | G9: 3200 | H9: 31 | I9: 3300 | J9: 3200 | K9: 31 | L9: 3300 | M9: 3200 | N9: 31 | O9: 4000 | P9: 6600 | Q9: 3933.589 | R9: 5313.199 | T9: Native Ericsson | U9: Native01 | V9: PEDĐ_HLC_05/06 | X9: =LEFT(B9,6) -> SGHL08 | AB9: PEPS_HLC_07/08 | AC9: TCHL10 | AD9: =SUMIF($U$5:$V$48,AC9,$L$5:$L$48) -> 6000 | AF9: =SUMIF($U$5:$V$48,AC9,$O$5:$O$48) -> 7200 | AH9: =SUMIF($U$5:$V$48,AC9,$Q$5:$Q$48) -> 0 | AL9: down
A10: =LEFT(B10,6) -> SGHL09 | B10: SGHL09 (Backup) | C10: 3000 | D10: 3000 | E10: 28 | F10: 3300 | G10: 3300 | H10: 28 | I10: 3300 | J10: 3300 | K10: 28 | L10: 3300 | M10: 3300 | N10: 28 | O10: 4000 | P10: 6600 | Q10: 3325.039 | R10: 4402.585 | T10: Native Ericsson | U10: Native01 | V10: PEDĐ_HLC_05/06 | X10: =LEFT(B10,6) -> SGHL09 | Z10: KV2 | AA10: ĐNG01 (Eric) | AB10: PEDĐ_HKH_03/04 | AC10: Native02 | AD10: =SUMIF($U$5:$V$48,AC10,$L$5:$L$48) -> 6900 | AE10: =AD10+AD11 -> 9200 | AF10: =SUMIF($U$5:$V$48,AC10,$O$5:$O$48) -> 7800 | AG10: =AF10+AF11 -> 10400 | AH10: =SUMIF($U$5:$V$48,AC10,$Q$5:$Q$48) -> 5170.04 | AI10: =SUM(AH10:AH11) -> 7197.438 | AJ10: =AI10/(AE10-AD11) -> 1.043107 | AK10: =AI10/(AG10-AF11) -> 0.92274846
A11: =LEFT(B11,6) -> SGHL10 | B11: SGHL10 | C11: 2500 | D11: 5000 | F11: 3300 | G11: 6600 | I11: 3300 | J11: 6600 | L11: 3300 | M11: 6600 | O11: 4000 | P11: 6600 | Q11: 2469.707 | R11: 3254.81 | T11: NFV Ericsson | U11: TCHL01 | V11: PEPS_HLC_05/06 | X11: =LEFT(B11,6) -> SGHL10 | AB11: PEPS_HKH_03/04 | AC11: TCHK01 | AD11: =SUMIF($U$5:$V$48,AC11,$L$5:$L$48) -> 2300 | AF11: =SUMIF($U$5:$V$48,AC11,$O$5:$O$48) -> 2600 | AH11: =SUMIF($U$5:$V$48,AC11,$Q$5:$Q$48) -> 2027.398 | AL11: down
A12: =LEFT(B12,6) -> SGHL11 | B12: SGHL11 (Backup) | F12: 3300 | G12: 6600 | I12: 3300 | J12: 6600 | L12: 3300 | M12: 6600 | O12: 4000 | P12: 6600 | Q12: 2659.326 | R12: 3501.768 | T12: NFV Ericsson | U12: TCHL01 | V12: PEPS_HLC_05/06 | X12: =LEFT(B12,6) -> SGHL11 | AA12: ĐNG02 (VHT) | AB12: PEPS_HKH_03/04 | AC12: TCHK02 | AD12: =SUMIF($U$5:$V$48,AC12,$L$5:$L$48) -> 4500 | AE12: =AD12+AD13+AD14 -> 10500 | AF12: =SUMIF($U$5:$V$48,AC12,$O$5:$O$48) -> 4500 | AG12: =AF12+AF13+AF14 -> 10500 | AH12: =SUMIF($U$5:$V$48,AC12,$Q$5:$Q$48) -> 2573.835 | AI12: =AH12 -> 2573.835 | AJ12: =AH12/(AF12+AF13) -> 0.343178 | AK12: =AJ12 -> 0.343178
A13: =LEFT(B13,6) -> SGHL12 | B13: SGHL12 | F13: 3300 | G13: 6600 | I13: 3300 | J13: 6600 | L13: 3300 | M13: 6600 | O13: 4000 | P13: 6600 | Q13: 2714.895 | R13: 3678.776 | T13: NFV Ericsson | U13: TCHL02 | V13: PEPS_HLC_05/06 | X13: =LEFT(B13,6) -> SGHL12 | AB13: PEPS_HKH_03/04 | AC13: TCHK06 | AD13: 3000 | AF13: 3000
A14: =LEFT(B14,6) -> SGHL13 | B14: SGHL13 | F14: 3300 | G14: 6600 | I14: 3300 | J14: 6600 | L14: 3300 | M14: 6600 | O14: 4000 | P14: 6600 | Q14: 2699.862 | R14: 3656.538 | T14: NFV Ericsson | U14: TCHL02 | V14: PEPS_HLC_05/06 | X14: =LEFT(B14,6) -> SGHL13 | AB14: PEPS_HKH_03/04 | AC14: TCHK07 | AD14: 3000 | AF14: 3000 | AL14: down
A15: =LEFT(B15,6) -> SGHL14 | B15: SGHL14 | I15: 2000 | J15: 4000 | L15: 2000 | M15: 4000 | O15: 2400 | P15: 4000 | Q15: 659.701 | R15: 0 | T15: NFV Ericsson | U15: TCHL01 | V15: PEPS_HLC_05/06 | X15: =LEFT(B15,6) -> SGHL14 | Z15: KV3 | AA15: HCM01 (Eric) | AB15: PEPS_HHT_01/02 | AC15: Native03 | AD15: =SUMIF($U$5:$V$48,AC15,$L$5:$L$48) -> 15400 | AE15: =AD15+AD16 -> 26600 | AF15: =SUMIF($U$5:$V$48,AC15,$O$5:$O$48) -> 17000 | AG15: =AF15+AF16 -> 30000 | AH15: =SUMIF($U$5:$V$48,AC15,$Q$5:$Q$48) -> 10600.005 | AI15: =15900 -> 15900 | AJ15: =AI15/(AE15-AD16) -> 1.0324675 | AK15: =AI15/(AG15-AF16) -> 0.93529412
A16: =LEFT(B16,6) -> SGHL15 | B16: SGHL15 (Backup) | I16: 2000 | J16: 4000 | L16: 2000 | M16: 4000 | O16: 2400 | P16: 4000 | Q16: 614.484 | R16: 0 | T16: NFV Ericsson | U16: TCHL02 | V16: PEPS_HLC_05/06 | X16: =LEFT(B16,6) -> SGHL15 | AB16: PEPS_HHT_03/04 | AC16: TCHT01 | AD16: =SUMIF($U$5:$V$48,AC16,$L$5:$L$48) -> 11200 | AF16: =SUMIF($U$5:$V$48,AC16,$O$5:$O$48) -> 13000 | AH16: =SUMIF($U$5:$V$48,AC16,$Q$5:$Q$48) -> 9317.759 | AL16: down
A17: =LEFT(B17,6) -> SGHL16 | B17: SGHL16 | L17: 2000 | M17: 4000 | O17: 2400 | P17: 4000 | Q17: 0 | R17: 0 | S17: HNI02 | T17: NFV Ericsson | U17: TCHL04 | V17: PEPS_HLC_07/08 | X17: =LEFT(B17,6) -> SGHL16 | AA17: HCM02 (VHT) | AB17: PEPS_PLM_01/02 | AC17: TCPL04 | AD17: =SUMIF($U$5:$V$48,AC17,$L$5:$L$48) -> 5500 | AE17: =AD17+AD18 -> 10000 | AF17: =SUMIF($U$5:$V$48,AC17,$O$5:$O$48) -> 5500 | AG17: =AF17+AF18 -> 10000 | AH17: =SUMIF($U$5:$V$48,AC17,$Q$5:$Q$48) -> 181.393 | AI17: =SUM(AH15:AH18)-AI15 -> 4199.157 | AJ17: =AI17/(AE17-AD17) -> 0.933146 | AK17: =AI17/(AG17-AF17) -> 0.933146 | AL17: down
A18: =LEFT(B18,6) -> SGHL17 | B18: SGHL17 | L18: 2000 | M18: 4000 | O18: 2400 | P18: 4000 | Q18: 0 | R18: 0 | T18: NFV Ericsson | U18: TCHL04 | V18: PEPS_HLC_07/08 | X18: =LEFT(B18,6) -> SGHL17 | AB18: PEPS_HHT_03/04 | AC18: TCHT10 | AD18: =SUMIF($U$5:$V$48,AC18,$L$5:$L$48) -> 4500 | AF18: =SUMIF($U$5:$V$48,AC18,$O$5:$O$48) -> 4500 | AH18: =SUMIF($U$5:$V$48,AC18,$Q$5:$Q$48) -> 0
A19: =LEFT(B19,6) -> SGHL18 | B19: SGHL18 (Backup) | L19: 2000 | M19: 4000 | O19: 2400 | P19: 4000 | Q19: 0 | R19: 0 | T19: NFV Ericsson | U19: TCHL04 | V19: PEPS_HLC_07/08 | X19: =LEFT(B19,6) -> SGHL18
A20: =LEFT(B20,6) -> SGHL23 | B20: SGHL23 | L20: 3000 | M20: 6000 | O20: 3600 | P20: 6000 | Q20: 0 | R20: 0 | T20: NFV Ericsson | U20: TCHL10 | V20: PEPS_HLC_07/08 | W20: Triển khai Q4/2024 | X20: =LEFT(B20,6) -> SGHL23
A21: =LEFT(B21,6) -> SGHL24 | B21: SGHL24 (backup | L21: 3000 | M21: 6000 | O21: 3600 | P21: 6000 | Q21: 0 | R21: 0 | T21: NFV Ericsson | U21: TCHL10 | V21: PEPS_HLC_07/08 | W21: Triển khai Q4/2024 | X21: =LEFT(B21,6) -> SGHL24
A22: =LEFT(B22,6) -> Total | B22: Total Hanoi | C22: =SUM(C5:C19)-C10 -> 17400 | D22: =SUM(D5:D19)-D10 -> 19200 | E22: =SUM(E5:E19)-E10 -> 149 | F22: =SUM(F5:F19)-F10-F12 -> 24800 | G22: =SUM(G5:G19)-G10-G12 -> 34000 | H22: =SUM(H5:H19)-H10-H12 -> 149 | I22: =SUM(I5:I19)-I10-I12-I16-I19 -> 26800 | J22: =SUM(J5:J19)-J10-J12-J16-J19 -> 38000 | K22: =SUM(K5:K19)-K10-K12-K16-K19 -> 149 | L22: =SUM(L5:L21)-L10-L12-L16-L19-L21 -> 33800 | M22: =SUM(M5:M21)-M10-M12-M16-M19-M21 -> 52000 | N22: =SUM(N5:N21)-N10-N12-N16-N19-N21 -> 149 | X22: =LEFT(B22,6) -> Total
A23: =LEFT(B23,6) -> SGHK01 | B23: SGHK01 (MKVIII) | C23: 2300 | D23: 2200 | E23: 25 | F23: 2300 | G23: 2200 | H23: 25 | I23: 2300 | J23: 2200 | K23: 25 | L23: 2300 | M23: 2300 | N23: 25 | O23: 2600 | P23: 4600 | Q23: 1717.693 | R23: 2102.07 | S23: DNG01 | T23: Native Ericsson | U23: Native02 | V23: PEPS_HKH_01/02 | X23: =LEFT(B23,6) -> SGHK01
A24: =LEFT(B24,6) -> SGHK02 | B24: SGHK02 (MKVIII) | C24: 2300 | D24: 2200 | E24: 25 | F24: 2300 | G24: 2200 | H24: 25 | I24: 2300 | J24: 2200 | K24: 25 | L24: 2300 | M24: 2300 | N24: 25 | O24: 2600 | P24: 4600 | Q24: 1732.817 | R24: 2098.484 | T24: Native Ericsson | U24: Native02 | V24: PEPS_HKH_01/02 | X24: =LEFT(B24,6) -> SGHK02
A25: =LEFT(B25,6) -> SGHK03 | B25: SGHK03 (Backup) | C25: 1750 | D25: 1750 | E25: 20 | F25: 2300 | G25: 2300 | H25: 28 | I25: 2300 | J25: 2300 | K25: 20 | L25: 2300 | M25: 2300 | N25: 20 | O25: 2600 | P25: 4600 | Q25: 1719.53 | R25: 2086.203 | T25: Native Ericsson | U25: Native02 | V25: PEPS_HKH_01/02 | X25: =LEFT(B25,6) -> SGHK03
A26: =LEFT(B26,6) -> SGHK06 | B26: SGHK06 | F26: 2300 | G26: 4600 | I26: 2300 | J26: 4600 | L26: 2300 | M26: 4600 | O26: 2600 | P26: 4600 | Q26: 2027.398 | R26: 2510.437 | T26: NFV Ericsson | U26: TCHK01 | V26: PEPS_HKH_03/04 | X26: =LEFT(B26,6) -> SGHK06
A27: =LEFT(B27,6) -> SGHK14 | B27: SGHK14 | L27: 1500 | M27: 3000 | T27: NFV Ericsson | U27: TCHK03 | V27: PEPS_HKH_03/04 | W27: Triển khai Q4/2024
A28: =LEFT(B28,6) -> SGHK15 | B28: SGHK15 | L28: 1500 | M28: 3000 | T28: NFV Ericsson | U28: TCHK03 | V28: PEPS_HKH_03/04 | W28: Triển khai Q4/2024
A29: =LEFT(B29,6) -> SGHK07 | B29: SGHK07 | I29: 1500 | J29: 3000 | L29: 1500 | M29: 3000 | O29: 1500 | P29: 3000 | Q29: 954.451 | R29: 1194.495 | S29: DNG02 | T29: NFV VHT | U29: TCHK02 | V29: PEPS_HKH_03/04 | X29: =LEFT(B29,6) -> SGHK07
A30: =LEFT(B30,6) -> SGHK08 | B30: SGHK08 | I30: 1500 | J30: 3000 | L30: 1500 | M30: 3000 | O30: 1500 | P30: 3000 | Q30: 681.708 | R30: 853.158 | T30: NFV VHT | U30: TCHK02 | V30: PEPS_HKH_03/04 | X30: =LEFT(B30,6) -> SGHK08
A31: =LEFT(B31,6) -> SGHK09 | B31: SGHK09 (Backup) | I31: 1500 | J31: 3000 | L31: 1500 | M31: 3000 | O31: 1500 | P31: 3000 | Q31: 937.676 | R31: 1173.502 | T31: NFV VHT | U31: TCHK02 | V31: PEPS_HKH_03/04 | X31: =LEFT(B31,6) -> SGHK09
A32: =LEFT(B32,6) -> Total | B32: Total Danang | C32: =SUM(C23:C31)-C25-C31 -> 4600 | D32: =SUM(D23:D31)-D25-D31 -> 4400 | E32: =SUM(E23:E31)-E25-E31 -> 50 | F32: =SUM(F23:F31)-F25-F31 -> 6900 | G32: =SUM(G23:G31)-G25-G31 -> 9000 | H32: =SUM(H23:H31)-H25-H31 -> 50 | I32: =SUM(I23:I31)-I25-I31 -> 9900 | J32: =SUM(J23:J31)-J25-J31 -> 15000 | ... N32: =SUM(N23:N31)-N25-N31 -> 50 | X32: =LEFT(B32,6) -> Total
A33: =LEFT(B33,6) -> SGHT07 | B33: SGHT07 (MKVIII) | C33: 2500 | D33: 2400 | E33: 28 | F33: 2500 | G33: 2400 | H33: 28 | I33: 2500 | J33: 2400 | K33: 28 | L33: 2500 | M33: 2400 | N33: 28 | O33: 2500 | P33: 5000 | Q33: 1180.972 | R33: 1459.57 | S33: HCM01 | T33: Native Ericsson | U33: Native03 | V33: PEPS_HHT_01/02 | X33: =LEFT(B33,6) -> SGHT07
A34: =LEFT(B34,6) -> SGHT08 | B34: SGHT08 (MKVIII) | C34: 2500 | D34: 2400 | E34: 28 | F34: 2500 | G34: 2400 | H34: 28 | I34: 2500 | J34: 2400 | K34: 28 | L34: 2500 | M34: 2400 | N34: 28 | O34: 2500 | P34: 5000 | Q34: 1663.005 | R34: 2153.929 | T34: Native Ericsson | U34: Native03 | V34: PEPS_HHT_01/02 | X34: =LEFT(B34,6) -> SGHT08
A35: =LEFT(B35,6) -> SGHT09 | B35: SGHT09 (MKX) | C35: 3500 | D35: 3300 | E35: 28 | F35: 3500 | G35: 3300 | H35: 28 | I35: 3500 | J35: 3300 | K35: 28 | L35: 3500 | M35: 3300 | N35: 28 | O35: 4000 | P35: 7000 | Q35: 2063.404 | R35: 2620.047 | T35: Native Ericsson | U35: Native03 | V35: PEPS_HHT_01/02 | X35: =LEFT(B35,6) -> SGHT09
A36: =LEFT(B36,6) -> SGHT10 | B36: SGHT10 (MKX) | C36: 3500 | D36: 3300 | E36: 28 | F36: 3500 | G36: 3300 | H36: 28 | I36: 3500 | J36: 3300 | K36: 28 | L36: 3500 | M36: 3300 | N36: 28 | O36: 4000 | P36: 7000 | Q36: 2873.27 | R36: 3663.769 | T36: Native Ericsson | U36: Native03 | V36: PEPS_HHT_01/02 | X36: =LEFT(B36,6) -> SGHT10
A37: =LEFT(B37,6) -> SGHT11 | B37: SGHT11 (Backup) | C37: 2500 | D37: 2500 | E37: 26 | F37: 3400 | G37: 3400 | H37: 26 | I37: 3400 | J37: 3400 | K37: 26 | L37: 3400 | M37: 3400 | N37: 26 | O37: 4000 | P37: 6800 | Q37: 2819.354 | R37: 3615.476 | T37: Native Ericsson | U37: Native03 | V37: PEPS_HHT_01/02 | X37: =LEFT(B37,6) -> SGHT11
A38: =LEFT(B38,6) -> SGHT12 | B38: SGHT12 | C38: 2500 | D38: 5000 | F38: 3400 | G38: 6800 | I38: 3400 | J38: 6800 | L38: 3400 | M38: 6800 | O38: 4000 | P38: 6800 | Q38: 2965.342 | R38: 3867.571 | T38: NFV Ericsson | U38: TCHT01 | V38: PEPS_HHT_03/04 | X38: =LEFT(B38,6) -> SGHT12
A39: =LEFT(B39,6) -> SGHT13 | B39: SGHT13 (Backup) | F39: 3400 | G39: 6800 | I39: 3400 | J39: 6800 | L39: 3400 | M39: 6800 | O39: 4000 | P39: 6800 | Q39: 3061.511 | R39: 3976.897 | T39: NFV Ericsson | U39: TCHT01 | V39: PEPS_HHT_03/04 | X39: =LEFT(B39,6) -> SGHT13
A40: =LEFT(B40,6) -> SGHT14 | B40: SGHT14 | F40: 3400 | G40: 6800 | I40: 3400 | J40: 6800 | L40: 3400 | M40: 6800 | O40: 4000 | P40: 6800 | Q40: 3110.197 | R40: 4037.528 | T40: NFV Ericsson | U40: TCHT01 | V40: PEPS_HHT_03/04 | X40: =LEFT(B40,6) -> SGHT14
A41: =LEFT(B41,6) -> SGHT15 | B41: SGHT15 | I41: 1000 | J41: 2000 | L41: 1000 | M41: 2000 | O41: 1000 | P41: 2000 | Q41: 180.709 | R41: 237.608 | T41: NFV Ericsson | U41: TCHT01 | V41: PEPS_HHT_03/04 | X41: =LEFT(B41,6) -> SGHT15
...

Sheet GGSN-Lic
A1: Node Name | B1: Node Name | C1: 2016 | F1: Phase 1 (2016) | I1: Phase 2 and swap 2G (2017) | L1: ( Q4-2018) | O1: Current License ( Q1-2020) | R1: Existing | U1: Ordering | X1: Existing Board (PPB/SSC3) | Y1: Added Board | Z1: Targeted Board | AA1: Card Requirement | AB1: Node type | AC1: Remark/SW version | AD1: OSS/ENM | AE1: CPB/PPB | AG1: Target Q4/2021 | AI1: Targeted (Q4-2023) | AK1: Targeted (Q4-2024) | AM1: Vendor | AN1: TCC | AO1: PE-PS | AP1: CGNAT | AR1: KV | AS1: PE-PS/PE-DĐ | AT1: MME | AV1: GGSN/PGW | AX1: IMS | AZ1: % SAU | BA1: % Gbps | BB1: % IMS | BC1: Ghi chú
C2: KSAU | D2: KBearer | E2: Gbps | F2: KSAU | G2: KBearer | H2: Gbps | I2: KSAU | J2: KBearer | K2: Gbps | L2: KSAU | M2: KBearer | N2: Gbps | O2: KSAU | P2: KBearer | Q2: Gbps | R2: KSAU | S2: KBearer | T2: Gbps | U2: KBearer | V2: Gbps | AG2: KBearer | AH2: Gbps | AI2: KBearer | AJ2: Gbps | AK2: KBearer | AL2: Gbps | AT2: Số node | AU2: kSAU | AV2: Số node | AW2: Gbps | AX2: Số node | AY2: ksub
A3: =LEFT(B3,6) -> GGHL04 | B3: GGHL04 | D3: 2000 | E3: 60 | G3: 2000 | H3: 60 | J3: 2000 | K3: 60 | M3: 1500 | N3: 60 | P3: 1500 | Q3: 60 | S3: 1500 | T3: 60 | AG3: 1500 | AH3: 60 | AI3: 1500 | AJ3: 60 | AK3: 1500 | AL3: 60 | AM3: Native Ericsson | AN3: N/A | AO3: PEPS_HLC_03/04 | AP3: FWHL03/04 (120 Gbps) | AQ3: Cắt sang CGNATHL01/02 | AR3: KV1 | AS3: PEPS_HLC_03/04 | AT3: 2 | AU3: 5000 | AV3: 2 | AW3: 120 | AZ3: =AU3/$AU$14 -> 0.048216008 | BA3: =AW3/$AW$14 -> 0.014035088 | BB3: =AY3/$AY$14 -> 0
A4: =LEFT(B4,6) -> GGHL05 | B4: GGHL05 | D4: 2000 | E4: 60 | G4: 2000 | H4: 60 | J4: 2000 | K4: 60 | M4: 1500 | N4: 60 | P4: 1500 | Q4: 60 | S4: 1500 | T4: 60 | AG4: 1500 | AH4: 60 | AI4: 1500 | AJ4: 60 | AK4: 1500 | AL4: 60 | AM4: Native Ericsson | AN4: N/A | AO4: PEPS_HLC_03/04 | AP4: FWHL03/04 (120 Gbps) | AQ4: Cắt sang CGNATHL01/02 | AS4: PEDĐ_HLC_05/06 | AT4: 4 | AU4: 13200 | AV4: 7 | AW4: 760 | AZ4: =AU4/$AU$14 -> 0.12729026 | BA4: =AW4/$AW$14 -> 0.088888889 | BB4: =AY4/$AY$14 -> 0
A5: =LEFT(B5,6) -> GGHL06 | B5: GGHL06 | G5: 1250 | H5: 40 | J5: 1500 | K5: 60 | M5: 1500 | N5: 60 | P5: 1500 | Q5: 60 | S5: 1500 | T5: 60 | AG5: 1500 | AH5: 60 | AI5: 1500 | AJ5: 60 | AK5: 1500 | AL5: 60 | AM5: Native Ericsson | AN5: N/A | AO5: PEDĐ_HLC_05/06 | AP5: CGNATHL01/02 (416 Gbps) | AS5: PEPS_HLC_05/06 | AT5: 6 | AU5: 17200 | AV5: 8 | AW5: 1200 | AX5: =1+2 -> 3 | AY5: =3000+10000 -> 13000 | AZ5: =AU5/$AU$14 -> 0.16586307 | BA5: =AW5/$AW$14 -> 0.14035088 | BB5: =AY5/$AY$14 -> 0.26804124 | BC5: Gồm VIM dự phòng 5M sub VHT
A6: =LEFT(B6,6) -> GGHL07 | B6: GGHL07 | G6: 1250 | H6: 40 | J6: 1500 | K6: 60 | M6: 1500 | N6: 60 | P6: 1500 | Q6: 60 | S6: 1500 | T6: 60 | AG6: 1500 | AH6: 60 | AI6: 1500 | AJ6: 60 | AK6: 1500 | AL6: 60 | AM6: Native Ericsson | AN6: N/A | AO6: PEDĐ_HLC_05/06 | AP6: CGNATHL15/16 (450 Gbps) | AS6: PEPS_HLC_07/08 | AT6: 5 | AU6: 12000 | AV6: 8 | AW6: 1100 | AX6: 2 | AY6: =2*2500 -> 5000 | AZ6: =AU6/$AU$14 -> 0.11571842 | BA6: =AW6/$AW$14 -> 0.12865497 | BB6: =AY6/$AY$14 -> 0.10309278
A7: =LEFT(B7,6) -> GGHL08 | B7: GGHL08 | J7: 1500 | K7: 50 | M7: 2000 | N7: 80 | P7: 2250 | Q7: 100 | S7: 2700 | T7: 130 | U7: =S7-P7 -> 450 | V7: =T7-Q7 -> 30 | X7: 8 | Y7: =Z7-X7 -> 2 | Z7: =_xlfn.CEILING.MATH(T7/15)+1 -> 10 | AA7: =_xlfn.CEILING.MATH(T7/15) +1 -> 10 | AB7: Expansion | AC7: EPG 1.10 | AD7: OSS | AE7: 3 SSC1 + 8 SSC3 | AG7: 2800 | AH7: 135 | AI7: 2800 | AJ7: 135 | AK7: 2800 | AL7: 135 | AM7: Native Ericsson | AN7: N/A | AO7: PEDĐ_HLC_05/06 | AP7: CGNATHL15/16 (450 Gbps) | AS7: PEPS_PDL_01/02 | AT7: 0 | AU7: 0 | AV7: 4 | AW7: 550 | AX7: 4 | AY7: =4*2500 -> 10000 | AZ7: =AU7/$AU$14 -> 0 | BA7: =AW7/$AW$14 -> 0.064327485 | BB7: =AY7/$AY$14 -> 0.20618557
A8: =LEFT(B8,6) -> GGHL09 | B8: GGHL09 | J8: 1500 | K8: 50 | M8: 2000 | N8: 80 | P8: 2250 | Q8: 100 | S8: 2700 | T8: 130 | U8: =S8-P8 -> 450 | V8: =T8-Q8 -> 30 | X8: 8 | Y8: =Z8-X8 -> 2 | Z8: =_xlfn.CEILING.MATH(T8/15)+1 -> 10 | AA8: =_xlfn.CEILING.MATH(T8/15) +1 -> 10 | AB8: Expansion | AC8: EPG 1.10 | AD8: OSS | AE8: 3 SSC1 + 8 SSC3 | AG8: 2800 | AH8: 135 | AI8: 2800 | AJ8: 135 | AK8: 2800 | AL8: 135 | AM8: Native Ericsson | AN8: N/A | AO8: PEDĐ_HLC_05/06 | AP8: CGNATHL15/16 (450 Gbps) | AR8: KV2 | AS8: PEPS_HKH_01/02 | AT8: 3 | AU8: 6900 | AV8: 2 | AW8: 120 | AZ8: =AU8/$AU$14 -> 0.066538091 | BA8: =AW8/$AW$14 -> 0.014035088 | BB8: =AY8/$AY$14 -> 0
A9: =LEFT(B9,6) -> GGHL10 | B9: GGHL10 (Backup) | J9: 2000 | K9: 60 | M9: 2000 | N9: 80 | P9: 2000 | Q9: 80 | S9: 2500 | T9: 80 | V9: =T9-Q9 -> 0 | AA9: =_xlfn.CEILING.MATH(T9/15) +1 -> 7 | AC9: HW Only/EPG 2.x ( this node was upraded for 5G trial and still used OSS) | AG9: 2900 | AH9: 100 | AI9: 2900 | AJ9: 100 | AK9: 2900 | AL9: 100 | AM9: Native Ericsson | AN9: N/A | AO9: PEDĐ_HLC_05/06 | AP9: CGNATHL15/16 (450 Gbps) | AS9: PEDĐ_HKH_03/04 | AT9: 0 | AU9: 0 | AV9: 2 | AW9: 160 | AZ9: =AU9/$AU$14 -> 0 | BA9: =AW9/$AW$14 -> 0.01871345 | BB9: =AY9/$AY$14 -> 0
A10: =LEFT(B10,6) -> GGHL11 | B10: GGHL11 | P10: 1700 | Q10: 80 | S10: 2700 | T10: 130 | U10: =S10-P10 -> 1000 | V10: =T10-Q10 -> 50 | X10: 7 | Y10: =Z10-X10 -> 3 | Z10: =_xlfn.CEILING.MATH(T10/15)+1 -> 10 | AA10: =_xlfn.CEILING.MATH(T10/15) +1 -> 10 | AB10: Expansion | AC10: EPG 2.x | AD10: ENM | AE10: 9 SSC3 (2+7) | AG10: 2800 | AH10: 135 | AI10: 2800 | AJ10: 135 | AK10: 2800 | AL10: 135 | AM10: Native Ericsson | AN10: N/A | AO10: PEDĐ_HLC_05/06 | AP10: CGNATHL01/02 (416 Gbps) | AS10: PEPS_HKH_03/04 | AT10: 8 | AU10: 12800 | AV10: 13 | AW10: 1920 | AZ10: =AU10/$AU$14 -> 0.12343298 | BA10: =AW10/$AW$14 -> 0.2245614 | BB10: =AY10/$AY$14 -> 0 | BC10: Gồm VIM dự phòng 4 GGSN, 4 MME VHT
A11: =LEFT(B11,6) -> GGHL12 | B11: GGHL12 | P11: 1700 | Q11: 80 | S11: 2700 | T11: 130 | U11: =S11-P11 -> 1000 | V11: =T11-Q11 -> 50 | X11: 7 | Y11: =Z11-X11 -> 3 | Z11: =_xlfn.CEILING.MATH(T11/15)+1 -> 10 | AA11: =_xlfn.CEILING.MATH(T11/15) +1 -> 10 | AB11: Expansion | AC11: EPG 2.x | AD11: ENM | AE11: 9 SSC3 (2+7) | AG11: 2800 | AH11: 135 | AI11: 2800 | AJ11: 135 | AK11: 2800 | AL11: 135 | AM11: Native Ericsson | AN11: N/A | AO11: PEDĐ_HLC_05/06 | AP11: CGNATHL01/02 (416 Gbps) | AR11: KV3 | AS11: PEPS_HHT_01/02 | AT11: 5 | AU11: 15400 | AV11: 7 | AW11: 620 | AZ11: =AU11/$AU$14 -> 0.1485053 | BA11: =AW11/$AW$14 -> 0.07251462 | BB11: =AY11/$AY$14 -> 0
A12: =LEFT(B12,6) -> GGHL13 | B12: GGHL13 | AG12: 4000 | AH12: 150 | AI12: 4000 | AJ12: 150 | AK12: 4000 | AL12: 150 | AM12: NFV Ericsson | AN12: TCHL01 | AO12: PEPS_HLC_05/06 | AP12: CGNATHL11/12 (450 Gbps) | AS12: PEPS_HHT_03/04 | AT12: 7 | AU12: 15700 | AV12: 11 | AW12: 1450 | AX12: 5 | AY12: =3000+5000+3*2500 -> 15500 | AZ12: =AU12/$AU$14 -> 0.15139826 | BA12: =AW12/$AW$14 -> 0.16959064 | BB12: =AY12/$AY$14 -> 0.31958763
A13: =LEFT(B13,6) -> GGHL14 | B13: GGHL14 | AG13: 4000 | AH13: 150 | AI13: 4000 | AJ13: 150 | AK13: 4000 | AL13: 150 | AM13: NFV Ericsson | AN13: TCHL01 | AO13: PEPS_HLC_05/06 | AP13: CGNATHL07/08 (416 Gbps) | AS13: PEPS_PLM_01/02 | AT13: 4 | AU13: 5500 | AV13: 4 | AW13: 550 | AX13: 2 | AY13: =2*2500 -> 5000 | AZ13: =AU13/$AU$14 -> 0.053037608 | BA13: =AW13/$AW$14 -> 0.064327485 | BB13: =AY13/$AY$14 -> 0.10309278
A14: =LEFT(B14,6) -> GGHL15 | B14: GGHL15 | AG14: 4000 | AH14: 150 | AI14: 4000 | AJ14: 150 | AK14: 4000 | AL14: 150 | AM14: NFV Ericsson | AN14: TCHL02 | AO14: PEPS_HLC_05/06 | AP14: CGNATHL09/10 (416 Gbps) | AR14: SUM | AT14: =SUM(AT3:AT13) -> 44 | AU14: =SUM(AU3:AU13) -> 103700 | AV14: =SUM(AV3:AV13) -> 68 | AW14: =SUM(AW3:AW13) -> 8550 | AX14: =SUM(AX3:AX13) -> 16 | AY14: =SUM(AY3:AY13) -> 48500 | AZ14: =AU14/$AU$14 -> 1 | BA14: =AW14/$AW$14 -> 1 | BB14: =AY14/$AY$14 -> 1
A15: =LEFT(B15,6) -> GGHL16 | B15: GGHL16 (Backup) | AG15: 4000 | AH15: 150 | AI15: 4000 | AJ15: 150 | AK15: 4000 | AL15: 150 | AM15: NFV Ericsson | AN15: TCHL02 | AO15: PEPS_HLC_05/06 | AP15: CGNATHL11/12 (450 Gbps)
A16: =LEFT(B16,6) -> GGHL17 | B16: GGHL17 | AG16: 4000 | AH16: 150 | AI16: 4000 | AJ16: 150 | AK16: 4000 | AL16: 150 | AM16: NFV Ericsson | AN16: TCHL01 | AO16: PEPS_HLC_05/06 | AP16: CGNATHL07/08 (416 Gbps) | AX16: Capacity | AY16: Redundancy | AZ16: Capacity expansion | BA16: Redundancy expansion
A17: =LEFT(B17,6) -> GGHL18 | B17: GGHL18 | AG17: 4000 | AH17: 150 | AI17: 4000 | AJ17: 150 | AK17: 4000 | AL17: 150 | AM17: NFV Ericsson | AN17: TCHL01 | AO17: PEPS_HLC_05/06 | AP17: CGNATHL07/08 (416 Gbps) | AW17: IMS Eric | AX17: 16000 | AY17: 2500 | AZ17: 10000 | BA17: 2500 | BB17: =AX17+AZ17 -> 26000 | BC17: =AY17+BA17 -> 5000
A18: =LEFT(B18,6) -> GGHL25 | B18: GGHL25 | AG18: 4000 | AH18: 150 | AI18: 4000 | AJ18: 150 | AK18: 4000 | AL18: 150 | AM18: NFV Ericsson | AN18: TCHL02 | AO18: PEPS_HLC_05/06 | AP18: CGNATHL09/10 (416 Gbps) | AW18: IMS VHT | AX18: 25000 | AY18: =5000 -> 5000 | AZ18: 15000 | BA18: =5000 -> 5000 | BB18: =AX18+AZ18 -> 40000 | BC18: =AY18+BA18 -> 10000
A19: =LEFT(B19,6) -> GGHL26 | B19: GGHL26 | AI19: 4000 | AJ19: 150 | AK19: 4000 | AL19: 150 | AM19: NFV Ericsson | AN19: TCHL02 | AO19: PEPS_HLC_05/06 | AP19: CGNATHL09/10 (416 Gbps) | AW19: Total | AX19: =AX17+AX18 -> 41000 | AY19: =AY17+AY18 -> 7500 | AZ19: =AZ17+AZ18 -> 25000 | BA19: =BA17+BA18 -> 7500 | BB19: =AX19+AZ19 -> 66000 | BC19: =AY19+BA19 -> 15000
A20: =LEFT(B20,6) -> GGHL27 | B20: GGHL27 | AK20: 3500 | AL20: 100 | AM20: NFV Ericsson | AN20: TCHL04 | AO20: PEPS_HLC_07/08 | AP20: CGNATHL13/14 (750 Gbps)
A21: =LEFT(B21,6) -> GGHL28 | B21: GGHL28 | AK21: 3500 | AL21: 100 | AM21: NFV Ericsson | AN21: TCHL04 | AO21: PEPS_HLC_07/08 | AP21: CGNATHL13/14 (750 Gbps) | AW21: 2024 | AX21: SAU | AY21: Mbps | AZ21: IMS
A22: =LEFT(B22,6) -> GGHL29 | B22: GGHL29 | AK22: 4500 | AL22: 150 | AM22: NFV Ericsson | AN22: TCHL04 | AO22: PEPS_HLC_07/08 | AP22: CGNATHL13/14 (750 Gbps) | AW22: HLC | AX22: ='[11]SGSN-MME'!K22 -> 33800 | AY22: =AL32-AL24-AL25-AL26 -> 2630 | AZ22: =AY5+AY6-7500 -> 10500
A23: =LEFT(B23,6) -> GGHL30 | B23: GGHL30 (Backup) | AK23: 4500 | AL23: 150 | AM23: NFV Ericsson | AN23: TCHL04 | AO23: PEPS_HLC_07/08 | AP23: CGNATHL13/14 (750 Gbps) | AW23: Total | AX23: ='[11]SGSN-MME'!K50 -> 73500 | AY23: =AL70 -> 6090 | AZ23: =AY14-AY19 -> 41000
A24: =LEFT(B24,6) -> GGPD04 | B24: GGPD04 | AK24: 4500 | AL24: 150 | AM24: NFV VHT | AN24: TCPD07 | AO24: PEPS_PDL_01/02 | AP24: CGNATPD01/02 (600 Gbps) | AW24: % HLC | AX24: =AX22/AX23 -> 0.45986395 | AY24: =AY22/AY23 -> 0.4318555 | AZ24: =AZ22/AZ23 -> 0.25609756
A25: =LEFT(B25,6) -> GGPD05 | B25: GGPD05 | AK25: 4500 | AL25: 150 | AM25: NFV VHT | AN25: TCPD07 | AO25: PEPS_PDL_01/02 | AP25: CGNATPD01/02 (600 Gbps)
A26: =LEFT(B26,6) -> GGPD06 | B26: GGPD06 | AK26: 3500 | AL26: 100 | AM26: NFV VHT | AN26: TCPD07 | AO26: PEPS_PDL_01/02 | AP26: CGNATPD01/02 (600 Gbps) | AW26: 2026 | AX26: SAU | AY26: Mbps
A27: =LEFT(B27,6) -> GGPD07 | B27: GGPD07 (Backup) | AK27: 4500 | AL27: 150 | AM27: NFV VHT | AN27: TCPD07 | AO27: PEPS_PDL_01/02 | AP27: CGNATPD01/02 (600 Gbps) | AW27: HLC | AX27: =AX22-'[11]SGSN-MME'!K7-'[11]SGSN-MME'!K8-'[11]SGSN-MME'!K9 -> 23900 | AY27: =AY22-AL3-AL4-AL5-AL6-AL7-AL8 -> 2120 | AZ27: =AY22-AY27 -> 510
A28: =LEFT(B28,6) -> GGHL31 | B28: GGHL31 | AK28: 4500 | AL28: 150 | AM28: NFV Ericsson | AN28: TCHL10 | AO28: PEPS_HLC_07/08 | AP28: CGNATHL13/14 (750 Gbps) | AQ28: Triển khai Q4/2024 | AW28: Total | AX28: =AX23+5000 -> 78500 | AY28: =AY23+750 -> 6840
A29: =LEFT(B29,6) -> GGHL32 | B29: GGHL32 | AK29: 4500 | AL29: 150 | AM29: NFV Ericsson | AN29: TCHL10 | AO29: PEPS_HLC_07/08 | AP29: CGNATHL13/14 (750 Gbps) | AQ29: Triển khai Q4/2024 | AW29: % HLC | AX29: =AX27/AX28 -> 0.3044586 | AY29: =AY27/AY28 -> 0.30994152
A30: =LEFT(B30,6) -> GGHL33 | B30: GGHL33 | AK30: 4500 | AL30: 150 | AM30: NFV Ericsson | AN30: TCHL10 | AO30: PEPS_HLC_07/08 | AP30: CGNATHL13/14 (750 Gbps) | AQ30: Triển khai Q4/2024 | AW30: Note | AX30: Tăng 5M 5G | AY30: Tăng 750G 5G
A31: =LEFT(B31,6) -> GGHL34 | B31: GGHL34 (Backup) | AK31: 4500 | AL31: 150 | AM31: NFV Ericsson | AN31: TCHL10 | AO31: PEPS_HLC_07/08 | AP31: CGNATHL13/14 (750 Gbps) | AQ31: Triển khai Q4/2024
A32: =LEFT(B32,6) -> Total | B32: Total Hanoi | D32: =SUM(D3:D8) -> 4000 | E32: =SUM(E3:E8) -> 120 | F32: =SUM(F3:F8) -> 0 | G32: =SUM(G3:G8) -> 6500 | H32: =SUM(H3:H8) -> 200 | I32: =SUM(I3:I8) -> 0 | J32: =SUM(J3:J8) -> 10000 | K32: =SUM(K3:K8) -> 340 | ... O32: =SUM(O3:O8) -> 0 | P32: =SUM(P3:P11) -> 15900 | Q32: =SUM(Q3:Q11) -> 680 | R32: =SUM(R3:R8) -> 0 | S32: =SUM(S3:S11) -> 19300 | T32: =SUM(T3:T11) -> 840 | AG32: =SUM(AG3:AG22)-AG9-AG15 -> 41200 | AH32: =SUM(AH3:AH22)-AH9-AH15 -> 1680 | AI32: =SUM(AI3:AI27)-AI9-AI15-AI23-AI27 -> 45200 | AJ32: =SUM(AJ3:AJ27)-AJ9-AJ15-AJ23-AJ27 -> 1830 | AK32: =SUM(AK3:AK31)-AK9-AK15-AK23-AK27-AK31 -> 82700 | AL32: =SUM(AL3:AL31)-AL9-AL15-AL23-AL27-AL31 -> 3030
A33: =LEFT(B33,6) -> GGHK01 | B33: GGHK01 | D33: 1000 | E33: 20 | G33: 1500 | H33: 35 | J33: 1750 | K33: 50 | M33: 1750 | N33: 60 | P33: 1500 | Q33: 60 | S33: 1500 | T33: 60 | U33: =S33-P33 -> 0 | V33: =T33-Q33 -> 0 | Y33: =Z33-X33 -> 0 | AA33: =_xlfn.CEILING.MATH(T33/15) +1 -> 5 | AC33: Move 250K PDP to GGHL08 | AG33: 1500 | AH33: 60 | AI33: 1500 | AJ33: 60 | AK33: 1500 | AL33: 60 | AM33: Native Ericsson | AN33: N/A | AO33: PEPS_HKH_01/02 | AP33: FWHK01/02 (120 Gbps) | AQ33: Cắt sang CGNATHK01/02
A34: =LEFT(B34,6) -> GGHK02 | B34: GGHK02 | D34: 1000 | E34: 20 | G34: 1500 | H34: 35 | J34: 1750 | K34: 50 | M34: 1750 | N34: 60 | P34: 1500 | Q34: 60 | S34: 1500 | T34: 60 | U34: =S34-P34 -> 0 | V34: =T34-Q34 -> 0 | Y34: =Z34-X34 -> 0 | AA34: =_xlfn.CEILING.MATH(T34/15) +1 -> 5 | AC34: Move 250K PDP to GGHL09 | AG34: 1500 | AH34: 60 | AI34: 1500 | AJ34: 60 | AK34: 1500 | AL34: 60 | AM34: Native Ericsson | AN34: N/A | AO34: PEPS_HKH_01/02 | AP34: FWHK01/02 (120 Gbps) | AQ34: Cắt sang CGNATHK01/02
A35: =LEFT(B35,6) -> GGHK03 | B35: GGHK03 (Backup) | J35: 1750 | K35: 50 | M35: 1750 | N35: 60 | P35: 1750 | Q35: 60 | S35: 1750 | T35: 60 | V35: =T35-Q35 -> 0 | Y35: =Z35-X35 -> 0 | AA35: =_xlfn.CEILING.MATH(T35/15) +1 -> 5 | AC35: HW Only/EPG 1.10 | AG35: 2000 | AH35: 70 | AI35: 2000 | AJ35: 70 | AK35: 2000 | AL35: 70 | AM35: Native Ericsson | AN35: N/A | AO35: PEDĐ_HKH_03/04 | AP35: CGNATHK01/02 (208 Gbps)
A36: =LEFT(B36,6) -> GGHK06 | B36: GGHK06 | P36: 1600 | Q36: 80 | S36: 1800 | T36: 90 | U36: =S36-P36 -> 200 | V36: =T36-Q36 -> 10 | X36: 7 | Y36: =Z36-X36 -> 0 | Z36: =_xlfn.CEILING.MATH(T36/15)+1 -> 7 | AA36: =_xlfn.CEILING.MATH(T36/15) +1 -> 7 | AB36: Expansion | AC36: EPG 2.x | AD36: ENM | AE36: 9 SSC3 (2+7) | AG36: 1800 | AH36: 90 | AI36: 1800 | AJ36: 90 | AK36: 1800 | AL36: 90 | AM36: Native Ericsson | AN36: N/A | AO36: PEDĐ_HKH_03/04 | AP36: CGNATHK01/02 (208 Gbps)
A37: =LEFT(B37,6) -> GGHK07 | B37: GGHK07 | AG37: 4000 | AH37: 150 | AI37: 4000 | AJ37: 150 | AK37: 4000 | AL37: 150 | AM37: NFV Ericsson | AN37: TCHK01 | AO37: PEPS_HKH_03/04 | AP37: CGNATHK03/04 (260 Gbps)
A38: =LEFT(B38,6) -> GGHK08 | B38: GGHK08 (Backup) | AG38: 4000 | AH38: 150 | AI38: 4000 | AJ38: 150 | AK38: 4000 | AL38: 150 | AM38: NFV Ericsson | AN38: TCHK01 | AO38: PEPS_HKH_03/04 | AP38: CGNATHK03/04 (260 Gbps)
A39: =LEFT(B39,6) -> GGHK09 | B39: GGHK09 | AG39: 4000 | AH39: 150 | AI39: 4000 | AJ39: 150 | AK39: 4000 | AL39: 150 | AM39: NFV Ericsson | AN39: TCHK01 | AO39: PEPS_HKH_03/04 | AP39: CGNATHK07/08 (600 Gbps)
A40: =LEFT(B40,6) -> GGHK13 | B40: GGHK13 | AK40: 4500 | AL40: 150 | AM40: NFV Ericsson | AN40: TCHK03 | AO40: PEPS_HKH_03/04 | AP40: CGNATHK07/08 (600 Gbps)
...

Sheet Input_Lic_Rate_PS
E1: License | N1: License | X1: SGSN | Y1: RMC
A2: STT | B2: Node | C2: VENDOR | D2: Khu vực | E2: License SAU | F2: License SAU (VHKT) | G2: Hardware version | H2: Software version | I2: RMC | J2: STT | K2: Node | L2: Vendor | M2: Khu vực | N2: Bear | O2: Throughput VHKT | P2: Throughput Node | Q2: Total IPv4 | R2: Total IPv6 | S2: Hardware/cloud_name | T2: Software version | U2: spgw zone | V2: Weight | W2: GGSN IP | X2: NE_NAME | Y2: relative_capacity | Z2: relative_capacity | AA2: mme_code | AB2: mme_group
A3: 1 | B3: SGHL04 | C3: Ericsson | D3: KV1-Pool1 | E3: 2500000 | F3: 2800000 | G3: MkVIII | H3: 1.65 | I3: =VLOOKUP(B3,X:Y,2,FALSE) -> 18 | J3: 1 | K3: GGPD04 | L3: VHT | M3: KV1 | N3: =VLOOKUP(K3,'Chi tiết_report'!$B$123:$S$175,16,FALSE) -> 4500000 | O3: =VLOOKUP(K3,'Chi tiết_report'!$B$123:$S$175,7,FALSE) -> 150000 | P3: 150000 | Q3: =VLOOKUP(K3,'Chi tiết_report'!$B$123:$S$175,18,FALSE) -> 4500000 | R3: =VLOOKUP(K3,'Chi tiết_report'!$B$123:$Z$175,24,FALSE) -> 0 | S3: TCPD07 | U3: =LOWER(CONCATENATE(K3,".",IF(L3="Ericsson","eric",IF(L3="VHT","viettel","cisco")),".zone",RIGHT(M3,1))) -> ggpd04.viettel.zone1 | V3: =VLOOKUP(K3,idns_weight_PCSCF!A:B,2,FALSE) -> Viettel | X3: SGHL04 | Y3: 18 | Z3: 18 | AA3: 4 | AB3: 32769
A4: =A3+1 -> 2 | B4: SGHL05 | C4: Ericsson | D4: KV1-Pool1 | E4: 2500000 | F4: 2800000 | G4: MkVIII | H4: 1.65 | I4: =VLOOKUP(B4,X:Y,2,FALSE) -> 18 | J4: 2 | K4: GGPD05 | L4: VHT | M4: KV1 | N4: =VLOOKUP(K4,'Chi tiết_report'!$B$123:$S$175,16,FALSE) -> 4500000 | O4: =VLOOKUP(K4,'Chi tiết_report'!$B$123:$S$175,7,FALSE) -> 150000 | P4: 150000 | Q4: =VLOOKUP(K4,'Chi tiết_report'!$B$123:$S$175,18,FALSE) -> 4500000 | R4: =VLOOKUP(K4,'Chi tiết_report'!$B$123:$Z$175,24,FALSE) -> 0 | S4: TCPD07 | U4: =LOWER(CONCATENATE(K4,".",IF(L4="Ericsson","eric",IF(L4="VHT","viettel","cisco")),".zone",RIGHT(M4,1))) -> ggpd05.viettel.zone1 | V4: =VLOOKUP(K4,idns_weight_PCSCF!A:B,2,FALSE) -> Viettel | X4: SGHL05 | Y4: 18 | Z4: 18 | AA4: 8 | AB4: 32769
A5: =A4+1 -> 3 | B5: SGHL06 | C5: Ericsson | D5: KV1-Pool1 | E5: 3300000 | F5: 3300000 | G5: MkX | H5: 1.84 | I5: =VLOOKUP(B5,X:Y,2,FALSE) -> 38 | J5: 3 | K5: GGPD06 | L5: VHT | M5: KV1 | N5: =VLOOKUP(K5,'Chi tiết_report'!$B$123:$S$175,16,FALSE) -> 4500000 | O5: =VLOOKUP(K5,'Chi tiết_report'!$B$123:$S$175,7,FALSE) -> 150000 | P5: 100000 | Q5: =VLOOKUP(K5,'Chi tiết_report'!$B$123:$S$175,18,FALSE) -> 4500000 | R5: =VLOOKUP(K5,'Chi tiết_report'!$B$123:$Z$175,24,FALSE) -> 0 | S5: TCPD07 | U5: =LOWER(CONCATENATE(K5,".",IF(L5="Ericsson","eric",IF(L5="VHT","viettel","cisco")),".zone",RIGHT(M5,1))) -> ggpd06.viettel.zone1 | V5: =VLOOKUP(K5,idns_weight_PCSCF!A:B,2,FALSE) -> Viettel | X5: SGHL06 | Y5: 38 | Z5: 38 | AA5: 12 | AB5: 32769
A6: =A5+1 -> 4 | B6: SGHL07 | C6: Ericsson | D6: KV1-Pool1 | E6: 3300000 | F6: 3300000 | G6: MkX | H6: 1.84 | I6: =VLOOKUP(B6,X:Y,2,FALSE) -> 38 | J6: 4 | K6: GGPD07 | L6: VHT | M6: KV1 | N6: =VLOOKUP(K6,'Chi tiết_report'!$B$123:$S$175,16,FALSE) -> 4500000 | O6: =VLOOKUP(K6,'Chi tiết_report'!$B$123:$S$175,7,FALSE) -> 150000 | P6: 150000 | Q6: =VLOOKUP(K6,'Chi tiết_report'!$B$123:$S$175,18,FALSE) -> 4500000 | R6: =VLOOKUP(K6,'Chi tiết_report'!$B$123:$Z$175,24,FALSE) -> 0 | S6: TCPD07 | U6: =LOWER(CONCATENATE(K6,".",IF(L6="Ericsson","eric",IF(L6="VHT","viettel","cisco")),".zone",RIGHT(M6,1))) -> ggpd07.viettel.zone1 | V6: =VLOOKUP(K6,idns_weight_PCSCF!A:B,2,FALSE) -> Viettel | X6: SGHL07 | Y6: 38 | Z6: 38 | AA6: 16 | AB6: 32769
A7: =A6+1 -> 5 | B7: SGHL08 | C7: Ericsson | D7: KV1-Pool1 | E7: 3300000 | F7: 3300000 | G7: MkX | H7: 1.84 | I7: =VLOOKUP(B7,X:Y,2,FALSE) -> 38 | J7: 5 | K7: GGHL04 | L7: Ericsson | M7: KV1 | N7: =VLOOKUP(K7,'Chi tiết_report'!$B$123:$S$175,16,FALSE) -> 1500000 | O7: =VLOOKUP(K7,'Chi tiết_report'!$B$123:$S$175,7,FALSE) -> 80000 | P7: 60000 | Q7: =VLOOKUP(K7,'Chi tiết_report'!$B$123:$S$175,18,FALSE) -> 1755000 | R7: =VLOOKUP(K7,'Chi tiết_report'!$B$123:$Z$175,24,FALSE) -> 1495000 | S7: SSR 8020 | T7: EPG 2.17 | U7: =LOWER(CONCATENATE(K7,".",IF(L7="Ericsson","eric",IF(L7="VHT","viettel","cisco")),".zone",RIGHT(M7,1))) -> gghl04.eric.zone1 | V7: =VLOOKUP(K7,idns_weight_PCSCF!A:B,2,FALSE) -> Ericsson | X7: SGHL08 | Y7: 38 | Z7: 38 | AA7: 40 | AB7: 32769
A8: =A7+1 -> 6 | B8: SGHL09 | C8: Ericsson | D8: KV1-Pool1 | E8: 3300000 | F8: 3300000 | G8: MkX | H8: 1.65 | I8: =VLOOKUP(B8,X:Y,2,FALSE) -> 38 | J8: 6 | K8: GGHL05 | L8: Ericsson | M8: KV1 | N8: 1500000 | O8: 80000 | P8: 60000 | Q8: =26*65535 -> 1703910 | R8: =VLOOKUP(K8,'Chi tiết_report'!$B$123:$Z$175,24,FALSE) -> 0 | S8: SSR 8020 | T8: EPG 2.17 | U8: =LOWER(CONCATENATE(K8,".",IF(L8="Ericsson","eric",IF(L8="VHT","viettel","cisco")),".zone",RIGHT(M8,1))) -> gghl05.eric.zone1 | V8: =VLOOKUP(K8,idns_weight_PCSCF!A:B,2,FALSE) -> Ericsson | X8: SGHL09 | Y8: 38 | Z8: 38 | AA8: 44 | AB8: 32769
A9: =A8+1 -> 7 | B9: SGHL10 | C9: Ericsson | D9: KV1-Pool1 | E9: 3300000 | F9: 3300000 | G9: Cloud-TCHL01 | H9: 1.61 | I9: =VLOOKUP(B9,X:Y,2,FALSE) -> 10 | J9: 7 | K9: GGHL06 | L9: Ericsson | M9: KV1 | N9: 1500000 | O9: 80000 | P9: 60000 | Q9: =VLOOKUP(K9,'Chi tiết_report'!$B$123:$S$175,18,FALSE) -> 0 | R9: =VLOOKUP(K9,'Chi tiết_report'!$B$123:$Z$175,24,FALSE) -> 0 | S9: SSR 8020 | T9: EPG 2.17 | U9: =LOWER(CONCATENATE(K9,".",IF(L9="Ericsson","eric",IF(L9="VHT","viettel","cisco")),".zone",RIGHT(M9,1))) -> gghl06.eric.zone1 | V9: =VLOOKUP(K9,idns_weight_PCSCF!A:B,2,FALSE) -> #N/A | X9: SGHL10 | Y9: 10 | Z9: 10 | AA9: 60 | AB9: 32769
A10: =A9+1 -> 8 | B10: SGHL11 | C10: Ericsson | D10: KV1-Pool1 | E10: 3300000 | F10: 3300000 | G10: Cloud-TCHL01 | H10: 1.61 | I10: =VLOOKUP(B10,X:Y,2,FALSE) -> 10 | J10: 8 | K10: GGHL07 | L10: Ericsson | M10: KV1 | N10: =VLOOKUP(K10,'Chi tiết_report'!$B$123:$S$175,16,FALSE) -> 1500000 | O10: =VLOOKUP(K10,'Chi tiết_report'!$B$123:$S$175,7,FALSE) -> 80000 | P10: 60000 | Q10: =VLOOKUP(K10,'Chi tiết_report'!$B$123:$S$175,18,FALSE) -> 1690000 | R10: =VLOOKUP(K10,'Chi tiết_report'!$B$123:$Z$175,24,FALSE) -> 1495000 | S10: SSR 8020 | T10: EPG 2.17 | U10: =LOWER(CONCATENATE(K10,".",IF(L10="Ericsson","eric",IF(L10="VHT","viettel","cisco")),".zone",RIGHT(M10,1))) -> gghl07.eric.zone1 | V10: =VLOOKUP(K10,idns_weight_PCSCF!A:B,2,FALSE) -> Ericsson | X10: SGHL11 | Y10: 10 | Z10: 10 | AA10: 92 | AB10: 32769
A11: =A10+1 -> 9 | B11: SGHL12 | C11: Ericsson | D11: KV1-Pool1 | E11: 3300000 | F11: 3300000 | G11: Cloud-TCHL02 | H11: 1.61 | I11: =VLOOKUP(B11,X:Y,2,FALSE) -> 38 | J11: 9 | K11: GGHL08 | L11: Ericsson | M11: KV1 | N11: =VLOOKUP(K11,'Chi tiết_report'!$B$123:$S$175,16,FALSE) -> 2800000 | O11: =VLOOKUP(K11,'Chi tiết_report'!$B$123:$S$175,7,FALSE) -> 150000 | P11: 135000 | Q11: =VLOOKUP(K11,'Chi tiết_report'!$B$123:$S$175,18,FALSE) -> 2990000 | R11: =VLOOKUP(K11,'Chi tiết_report'!$B$123:$Z$175,24,FALSE) -> 2730000 | S11: SSR 8020 | T11: EPG 2.17 | U11: =LOWER(CONCATENATE(K11,".",IF(L11="Ericsson","eric",IF(L11="VHT","viettel","cisco")),".zone",RIGHT(M11,1))) -> gghl08.eric.zone1 | V11: =VLOOKUP(K11,idns_weight_PCSCF!A:B,2,FALSE) -> Ericsson | X11: SGHL12 | Y11: 38 | Z11: 38 | AA11: 96 | AB11: 32769
A12: =A11+1 -> 10 | B12: SGHL13 | C12: Ericsson | D12: KV1-Pool1 | E12: 3300000 | F12: 3300000 | G12: Cloud-TCHL02 | H12: 1.61 | I12: =VLOOKUP(B12,X:Y,2,FALSE) -> 38 | J12: 10 | K12: GGHL09 | L12: Ericsson | M12: KV1 | N12: =VLOOKUP(K12,'Chi tiết_report'!$B$123:$S$175,16,FALSE) -> 2800000 | O12: =VLOOKUP(K12,'Chi tiết_report'!$B$123:$S$175,7,FALSE) -> 150000 | P12: 135000 | Q12: =VLOOKUP(K12,'Chi tiết_report'!$B$123:$S$175,18,FALSE) -> 2990000 | R12: =VLOOKUP(K12,'Chi tiết_report'!$B$123:$Z$175,24,FALSE) -> 2730000 | S12: SSR 8020 | T12: EPG 2.17 | U12: =LOWER(CONCATENATE(K12,".",IF(L12="Ericsson","eric",IF(L12="VHT","viettel","cisco")),".zone",RIGHT(M12,1))) -> gghl09.eric.zone1 | V12: =VLOOKUP(K12,idns_weight_PCSCF!A:B,2,FALSE) -> Ericsson | X12: SGHL13 | Y12: 38 | Z12: 38 | AA12: 100 | AB12: 32769
A13: =A12+1 -> 11 | B13: SGHL14 | C13: Ericsson | D13: KV1-Pool1 | E13: 2000000 | F13: 2000000 | G13: Cloud-TCHL01 | H13: 1.65 | I13: =VLOOKUP(B13,X:Y,2,FALSE) -> 10 | J13: 11 | K13: GGHL10 | L13: Ericsson | M13: KV1 | N13: =VLOOKUP(K13,'Chi tiết_report'!$B$123:$S$175,16,FALSE) -> 2400000 | O13: =VLOOKUP(K13,'Chi tiết_report'!$B$123:$S$175,7,FALSE) -> 100000 | P13: 100000 | Q13: =VLOOKUP(K13,'Chi tiết_report'!$B$123:$S$175,18,FALSE) -> 2470000 | R13: =VLOOKUP(K13,'Chi tiết_report'!$B$123:$Z$175,24,FALSE) -> 2015000 | S13: SSR 8020 | T13: EPG 2.17 | U13: =LOWER(CONCATENATE(K13,".",IF(L13="Ericsson","eric",IF(L13="VHT","viettel","cisco")),".zone",RIGHT(M13,1))) -> gghl10.eric.zone1 | V13: =VLOOKUP(K13,idns_weight_PCSCF!A:B,2,FALSE) -> Ericsson | X13: SGHL14 | Y13: 10 | Z13: 10 | AA13: 116 | AB13: 32769
A14: =A13+1 -> 12 | B14: SGHL15 | C14: Ericsson | D14: KV1-Pool1 | E14: 2000000 | F14: 2000000 | G14: Cloud-TCHL02 | H14: 1.65 | I14: =VLOOKUP(B14,X:Y,2,FALSE) -> 30 | J14: 12 | K14: GGHL11 | L14: Ericsson | M14: KV1 | N14: =VLOOKUP(K14,'Chi tiết_report'!$B$123:$S$175,16,FALSE) -> 2800000 | O14: =VLOOKUP(K14,'Chi tiết_report'!$B$123:$S$175,7,FALSE) -> 150000 | P14: 135000 | Q14: =VLOOKUP(K14,'Chi tiết_report'!$B$123:$S$175,18,FALSE) -> 2990000 | R14: =VLOOKUP(K14,'Chi tiết_report'!$B$123:$Z$175,24,FALSE) -> 2730000 | S14: SSR 8020 | T14: EPG 2.17 | U14: =LOWER(CONCATENATE(K14,".",IF(L14="Ericsson","eric",IF(L14="VHT","viettel","cisco")),".zone",RIGHT(M14,1))) -> gghl11.eric.zone1 | V14: =VLOOKUP(K14,idns_weight_PCSCF!A:B,2,FALSE) -> Ericsson | X14: SGHL15 | Y14: 30 | Z14: 30 | AA14: 120 | AB14: 32769
A15: =A14+1 -> 13 | B15: SGHL16 | C15: Ericsson | D15: KV1-Pool3 | E15: 2000000 | F15: 2000000 | G15: Cloud-TCHL04 | H15: 1.86 | I15: =VLOOKUP(B15,X:Y,2,FALSE) -> 20 | J15: 13 | K15: GGHL12 | L15: Ericsson | M15: KV1 | N15: =VLOOKUP(K15,'Chi tiết_report'!$B$123:$S$175,16,FALSE) -> 2800000 | O15: =VLOOKUP(K15,'Chi tiết_report'!$B$123:$S$175,7,FALSE) -> 150000 | P15: 135000 | Q15: =VLOOKUP(K15,'Chi tiết_report'!$B$123:$S$175,18,FALSE) -> 2990000 | R15: =VLOOKUP(K15,'Chi tiết_report'!$B$123:$Z$175,24,FALSE) -> 2730000 | S15: SSR 8020 | T15: EPG 2.17 | U15: =LOWER(CONCATENATE(K15,".",IF(L15="Ericsson","eric",IF(L15="VHT","viettel","cisco")),".zone",RIGHT(M15,1))) -> gghl12.eric.zone1 | V15: =VLOOKUP(K15,idns_weight_PCSCF!A:B,2,FALSE) -> Ericsson | X15: SGHK01 | Y15: 25 | Z15: 25 | AA15: 20 | AB15: 32770
A16: =A15+1 -> 14 | B16: SGHL17 | C16: Ericsson | D16: KV1-Pool3 | E16: 2000000 | F16: 2000000 | G16: Cloud-TCHL04 | H16: 1.86 | I16: =VLOOKUP(B16,X:Y,2,FALSE) -> 20 | J16: 14 | K16: GGHL13 | L16: Ericsson | M16: KV1 | N16: =VLOOKUP(K16,'Chi tiết_report'!$B$123:$S$175,16,FALSE) -> 4000000 | O16: =VLOOKUP(K16,'Chi tiết_report'!$B$123:$S$175,7,FALSE) -> 180000 | P16: 150000 | Q16: =VLOOKUP(K16,'Chi tiết_report'!$B$123:$S$175,18,FALSE) -> 4063232 | R16: =131072*31 -> 4063232 | S16: TCHL01 | T16: EPG 2.15 | U16: =LOWER(CONCATENATE(K16,".",IF(L16="Ericsson","eric",IF(L16="VHT","viettel","cisco")),".zone",RIGHT(M16,1))) -> gghl13.eric.zone1 | V16: =VLOOKUP(K16,idns_weight_PCSCF!A:B,2,FALSE) -> Ericsson | X16: SGHK02 | Y16: 25 | Z16: 25 | AA16: 24 | AB16: 32770
A17: =A16+1 -> 15 | B17: SGHL18 | C17: Ericsson | D17: KV1-Pool3 | E17: 2000000 | F17: 2000000 | G17: Cloud-TCHL04 | H17: 1.86 | I17: =VLOOKUP(B17,X:Y,2,FALSE) -> 20 | J17: 15 | K17: GGHL14 | L17: Ericsson | M17: KV1 | N17: =VLOOKUP(K17,'Chi tiết_report'!$B$123:$S$175,16,FALSE) -> 4000000 | O17: =VLOOKUP(K17,'Chi tiết_report'!$B$123:$S$175,7,FALSE) -> 180000 | P17: 150000 | Q17: =VLOOKUP(K17,'Chi tiết_report'!$B$123:$S$175,18,FALSE) -> 4063232 | R17: =131072*31 -> 4063232 | S17: TCHL01 | T17: EPG 2.15 | U17: =LOWER(CONCATENATE(K17,".",IF(L17="Ericsson","eric",IF(L17="VHT","viettel","cisco")),".zone",RIGHT(M17,1))) -> gghl14.eric.zone1 | V17: =VLOOKUP(K17,idns_weight_PCSCF!A:B,2,FALSE) -> Ericsson | X17: SGHK03 | Y17: 25 | Z17: 25 | AA17: 48 | AB17: 32770
B18: Pool KV1 | C18: Ericsson | E18: =SUM(E3:E17) -> 41400000 | F18: =SUM(F3:F17) -> 42000000 | J18: 16 | K18: GGHL15 | L18: Ericsson | M18: KV1 | N18: =VLOOKUP(K18,'Chi tiết_report'!$B$123:$S$175,16,FALSE) -> 4000000 | O18: =VLOOKUP(K18,'Chi tiết_report'!$B$123:$S$175,7,FALSE) -> 180000 | P18: 150000 | Q18: =VLOOKUP(K18,'Chi tiết_report'!$B$123:$S$175,18,FALSE) -> 4063232 | R18: =131072*31 -> 4063232 | S18: TCHL02 | T18: EPG 2.17 | U18: =LOWER(CONCATENATE(K18,".",IF(L18="Ericsson","eric",IF(L18="VHT","viettel","cisco")),".zone",RIGHT(M18,1))) -> gghl15.eric.zone1 | V18: =VLOOKUP(K18,idns_weight_PCSCF!A:B,2,FALSE) -> Ericsson | X18: SGHK06 | Y18: 25 | Z18: 25 | AA18: 104 | AB18: 32770
A19: 16 | B19: SGHL19 | C19: VHT | D19: KV1 | E19: 1000000 | F19: 1000000 | J19: 17 | K19: GGHL16 | L19: Ericsson | M19: KV1 | N19: =VLOOKUP(K19,'Chi tiết_report'!$B$123:$S$175,16,FALSE) -> 4000000 | O19: =VLOOKUP(K19,'Chi tiết_report'!$B$123:$S$175,7,FALSE) -> 180000 | P19: 150000 | Q19: =VLOOKUP(K19,'Chi tiết_report'!$B$123:$S$175,18,FALSE) -> 4063232 | R19: =131072*31 -> 4063232 | S19: TCHL02 | T19: EPG 2.16 | U19: =LOWER(CONCATENATE(K19,".",IF(L19="Ericsson","eric",IF(L19="VHT","viettel","cisco")),".zone",RIGHT(M19,1))) -> gghl16.eric.zone1 | V19: =VLOOKUP(K19,idns_weight_PCSCF!A:B,2,FALSE) -> Ericsson | X19: SGHK14 | Y19: 25 | Z19: 25 | AA19: 244 | AB19: 32770
A20: =A19+1 -> 17 | B20: SGHL20 | C20: VHT | D20: KV1 | E20: 1000000 | F20: 1000000 | J20: 18 | K20: GGHL17 | L20: Ericsson | M20: KV1 | N20: =VLOOKUP(K20,'Chi tiết_report'!$B$123:$S$175,16,FALSE) -> 4000000 | O20: =VLOOKUP(K20,'Chi tiết_report'!$B$123:$S$175,7,FALSE) -> 180000 | P20: 150000 | Q20: =VLOOKUP(K20,'Chi tiết_report'!$B$123:$S$175,18,FALSE) -> 4063232 | R20: =131072*31 -> 4063232 | S20: TCHL01 | U20: =LOWER(CONCATENATE(K20,".",IF(L20="Ericsson","eric",IF(L20="VHT","viettel","cisco")),".zone",RIGHT(M20,1))) -> gghl17.eric.zone1 | V20: =VLOOKUP(K20,idns_weight_PCSCF!A:B,2,FALSE) -> Ericsson | X20: SGHK15 | Y20: 25 | Z20: 25 | AA20: 248 | AB20: 32770
A21: =A20+1 -> 18 | B21: SGHL21 | C21: VHT | D21: KV1 | E21: 1000000 | F21: 1000000 | J21: 19 | K21: GGHL18 | L21: Ericsson | M21: KV1 | N21: =VLOOKUP(K21,'Chi tiết_report'!$B$123:$S$175,16,FALSE) -> 4000000 | O21: =VLOOKUP(K21,'Chi tiết_report'!$B$123:$S$175,7,FALSE) -> 180000 | P21: 150000 | Q21: =VLOOKUP(K21,'Chi tiết_report'!$B$123:$S$175,18,FALSE) -> 4063232 | R21: =131072*31 -> 4063232 | S21: TCHL01 | U21: =LOWER(CONCATENATE(K21,".",IF(L21="Ericsson","eric",IF(L21="VHT","viettel","cisco")),".zone",RIGHT(M21,1))) -> gghl18.eric.zone1 | V21: =VLOOKUP(K21,idns_weight_PCSCF!A:B,2,FALSE) -> Ericsson | X21: SGHT07 | Y21: 18 | Z21: 18 | AA21: 28 | AB21: 32771
B22: Pool KV1 | C22: VHT | E22: =SUM(E19:E21) -> 3000000 | F22: =SUM(F19:F21) -> 3000000 | J22: 20 | K22: GGHL25 | L22: Ericsson | M22: KV1 | N22: =VLOOKUP(K22,'Chi tiết_report'!$B$123:$S$175,16,FALSE) -> 4000000 | O22: =VLOOKUP(K22,'Chi tiết_report'!$B$123:$S$175,7,FALSE) -> 180000 | P22: 150000 | Q22: =131072*31 -> 4063232 | R22: =131072*31 -> 4063232 | S22: TCHL02 | T22: EPG 2.16 | U22: =LOWER(CONCATENATE(K22,".",IF(L22="Ericsson","eric",IF(L22="VHT","viettel","cisco")),".zone",RIGHT(M22,1))) -> gghl25.eric.zone1 | V22: =VLOOKUP(K22,idns_weight_PCSCF!A:B,2,FALSE) -> Ericsson | X22: SGHT08 | Y22: 12 | Z22: 12 | AA22: 32 | AB22: 32771
A23: 19 | B23: SGHK01 | C23: Ericsson | D23: KV2 | E23: 2300000 | F23: 2300000 | G23: MkVIII | H23: 1.65 | I23: =VLOOKUP(B23,X:Y,2,FALSE) -> 25 | J23: 21 | K23: GGHL26 | L23: Ericsson | M23: KV1 | N23: =VLOOKUP(K23,'Chi tiết_report'!$B$123:$S$175,16,FALSE) -> 4000000 | O23: =VLOOKUP(K23,'Chi tiết_report'!$B$123:$S$175,7,FALSE) -> 180000 | P23: 150000 | Q23: =65535*54 -> 3538890 | R23: =131072*31 -> 4063232 | S23: TCHL02 | T23: EPG 2.16 | U23: =LOWER(CONCATENATE(K23,".",IF(L23="Ericsson","eric",IF(L23="VHT","viettel","cisco")),".zone",RIGHT(M23,1))) -> gghl26.eric.zone1 | V23: =VLOOKUP(K23,idns_weight_PCSCF!A:B,2,FALSE) -> Ericsson | X23: SGHT09 | Y23: 38 | Z23: 38 | AA23: 36 | AB23: 32771
A24: =A23+1 -> 20 | B24: SGHK02 | C24: Ericsson | D24: KV2 | E24: 2300000 | F24: 2300000 | G24: MkVIII | H24: 1.65 | I24: =VLOOKUP(B24,X:Y,2,FALSE) -> 25 | J24: 22 | K24: GGHL27 | L24: Ericsson | M24: KV1 | N24: 3500000 | O24: 100000 | P24: 100000 | Q24: =131072*27 -> 3538944 | R24: =VLOOKUP(K24,'Chi tiết_report'!$B$123:$Z$175,24,FALSE) -> #N/A | S24: TCHL04 | T24: CUPS | U24: =LOWER(CONCATENATE(K24,".",IF(L24="Ericsson","eric",IF(L24="VHT","viettel","cisco")),".zone",RIGHT(M24,1))) -> gghl27.eric.zone1 | V24: 0 | X24: SGHT10 | Y24: 38 | Z24: 38 | AA24: 52 | AB24: 32771
A25: =A24+1 -> 21 | B25: SGHK03 | C25: Ericsson | D25: KV2 | E25: 2300000 | F25: 2300000 | G25: MkX | H25: 1.65 | I25: =VLOOKUP(B25,X:Y,2,FALSE) -> 25 | J25: 23 | K25: GGHL28 | L25: Ericsson | M25: KV1 | N25: 3500000 | O25: 100000 | P25: 100000 | Q25: =131072*27 -> 3538944 | R25: =VLOOKUP(K25,'Chi tiết_report'!$B$123:$Z$175,24,FALSE) -> #N/A | S25: TCHL04 | T25: CUPS | U25: =LOWER(CONCATENATE(K25,".",IF(L25="Ericsson","eric",IF(L25="VHT","viettel","cisco")),".zone",RIGHT(M25,1))) -> gghl28.eric.zone1 | V25: 0 | X25: SGHT11 | Y25: 38 | Z25: 38 | AA25: 56 | AB25: 32771
A26: =A25+1 -> 22 | B26: SGHK06 | C26: Ericsson | D26: KV2 | E26: 2300000 | F26: 2300000 | G26: Cloud-TCHK01 | H26: 1.50 | I26: =VLOOKUP(B26,X:Y,2,FALSE) -> 25 | J26: 24 | K26: GGHL29 | L26: Ericsson | M26: KV1 | N26: 4000000 | O26: 150000 | P26: 150000 | Q26: =131072*27 -> 3538944 | R26: =VLOOKUP(K26,'Chi tiết_report'!$B$123:$Z$175,24,FALSE) -> #N/A | S26: TCHL04 | T26: CUPS | U26: =LOWER(CONCATENATE(K26,".",IF(L26="Ericsson","eric",IF(L26="VHT","viettel","cisco")),".zone",RIGHT(M26,1))) -> gghl29.eric.zone1 | V26: 0 | X26: SGHT12 | Y26: 38 | Z26: 38 | AA26: 64 | AB26: 32771
B27: Pool KV2 | C27: Ericsson | E27: =SUM(E23:E26) -> 9200000 | F27: =SUM(F26:F26) -> 2300000 | J27: 25 | K27: GGHL30 | L27: Ericsson | M27: KV1 | N27: 4000000 | O27: 150000 | P27: 150000 | Q27: =131072*27 -> 3538944 | R27: =VLOOKUP(K27,'Chi tiết_report'!$B$123:$Z$175,24,FALSE) -> #N/A | S27: TCHL04 | T27: CUPS | U27: =LOWER(CONCATENATE(K27,".",IF(L27="Ericsson","eric",IF(L27="VHT","viettel","cisco")),".zone",RIGHT(M27,1))) -> gghl30.eric.zone1 | V27: 0 | X27: SGHT13 | Y27: 38 | Z27: 38 | AA27: 108 | AB27: 32771
A28: 23 | B28: SGHK07 | C28: VHT | D28: KV2 | E28: 1500000 | F28: 1500000 | G28: TCHK02 | J28: 22 | K28: GGHL31 | L28: Ericsson | M28: KV1 | N28: 3500000 | O28: 100000 | P28: 100000 | Q28: =131072*27 -> 3538944 | R28: =VLOOKUP(K28,'Chi tiết_report'!$B$123:$Z$175,24,FALSE) -> #N/A | S28: TCHL10 | T28: CUPS | U28: =LOWER(CONCATENATE(K28,".",IF(L28="Ericsson","eric",IF(L28="VHT","viettel","cisco")),".zone",RIGHT(M28,1))) -> gghl31.eric.zone1 | V28: 0 | X28: SGHT14 | Y28: 38 | Z28: 38 | AA28: 112 | AB28: 32771
A29: =A28+1 -> 24 | B29: SGHK08 | C29: VHT | D29: KV2 | E29: 1500000 | F29: 1500000 | G29: TCHK02 | J29: 23 | K29: GGHL32 | L29: Ericsson | M29: KV1 | N29: 3500000 | O29: 100000 | P29: 100000 | Q29: =131072*27 -> 3538944 | R29: =VLOOKUP(K29,'Chi tiết_report'!$B$123:$Z$175,24,FALSE) -> #N/A | S29: TCHL10 | T29: CUPS | U29: =LOWER(CONCATENATE(K29,".",IF(L29="Ericsson","eric",IF(L29="VHT","viettel","cisco")),".zone",RIGHT(M29,1))) -> gghl32.eric.zone1 | V29: 0 | X29: SGHT15 | Y29: 20 | Z29: 20 | AA29: 124 | AB29: 32771
A30: =A29+1 -> 25 | B30: SGHK09 | C30: VHT | D30: KV2 | E30: 1500000 | F30: 1500000 | G30: TCHK02 | J30: 24 | K30: GGHL33 | L30: Ericsson | M30: KV1 | N30: 4000000 | O30: 150000 | P30: 150000 | Q30: =131072*27 -> 3538944 | R30: =VLOOKUP(K30,'Chi tiết_report'!$B$123:$Z$175,24,FALSE) -> #N/A | S30: TCHL10 | T30: CUPS | U30: =LOWER(CONCATENATE(K30,".",IF(L30="Ericsson","eric",IF(L30="VHT","viettel","cisco")),".zone",RIGHT(M30,1))) -> gghl33.eric.zone1 | V30: 0 | X30: SGHK07 | Y30: 15 | Z30: 15 | AA30: 68 | AB30: 32773
A31: 23 | B31: SGHK10 | C31: VHT | D31: KV2 | E31: 1500000 | F31: 1500000 | G31: TCHK06 | H31: 2025 | J31: 25 | K31: GGHL34 | L31: Ericsson | M31: KV1 | N31: 4000000 | O31: 150000 | P31: 150000 | Q31: =131072*27 -> 3538944 | R31: =VLOOKUP(K31,'Chi tiết_report'!$B$123:$Z$175,24,FALSE) -> #N/A | S31: TCHL10 | T31: CUPS | U31: =LOWER(CONCATENATE(K31,".",IF(L31="Ericsson","eric",IF(L31="VHT","viettel","cisco")),".zone",RIGHT(M31,1))) -> gghl34.eric.zone1 | V31: 0 | X31: SGHK08 | Y31: 15 | Z31: 15 | AA31: 72 | AB31: 32773
A32: =A31+1 -> 24 | B32: SGHK11 | C32: VHT | D32: KV2 | E32: 1500000 | F32: 1500000 | G32: TCHK06 | H32: 2025 | I32: =VLOOKUP(B36,X:Y,2,FALSE) -> 18 | J32: 26 | K32: GGHL19 | L32: VHT | M32: KV1 | N32: =VLOOKUP(K32,'Chi tiết_report'!$B$123:$S$175,16,FALSE) -> 1500000 | O32: =VLOOKUP(K32,'Chi tiết_report'!$B$123:$S$175,7,FALSE) -> 80000 | P32: 60000 | Q32: =VLOOKUP(K32,'Chi tiết_report'!$B$123:$S$175,18,FALSE) -> 1500000 | R32: =VLOOKUP(K32,'Chi tiết_report'!$B$123:$Z$175,24,FALSE) -> 28376952 | S32: VHT | T32: EPG 2.16 | U32: =LOWER(CONCATENATE(K32,".",IF(L32="Ericsson","eric",IF(L32="VHT","viettel","cisco")),".zone",RIGHT(M32,1))) -> gghl19.viettel.zone1 | V32: =VLOOKUP(K32,idns_weight_PCSCF!A:B,2,FALSE) -> #N/A | X32: SGHK09 | Y32: 15 | Z32: 15 | AA32: 128 | AB32: 32773
A33: =A31+1 -> 24 | B33: SGHK12 | C33: VHT | D33: KV2 | E33: 1500000 | F33: 1500000 | G33: TCHK07 | I33: =VLOOKUP(B37,X:Y,2,FALSE) -> 12 | J33: 27 | K33: GGHL20 | L33: VHT | M33: KV1 | N33: =VLOOKUP(K33,'Chi tiết_report'!$B$123:$S$175,16,FALSE) -> 1000000 | O33: =VLOOKUP(K33,'Chi tiết_report'!$B$123:$S$175,7,FALSE) -> 70000 | P33: 60000 | Q33: =VLOOKUP(K33,'Chi tiết_report'!$B$123:$S$175,18,FALSE) -> 1114032 | R33: =VLOOKUP(K33,'Chi tiết_report'!$B$123:$Z$175,24,FALSE) -> 28376952 | S33: VHT | T33: EPG 2.16 | U33: =LOWER(CONCATENATE(K33,".",IF(L33="Ericsson","eric",IF(L33="VHT","viettel","cisco")),".zone",RIGHT(M33,1))) -> gghl20.viettel.zone1 | V33: =VLOOKUP(K33,idns_weight_PCSCF!A:B,2,FALSE) -> #N/A | X33: SGHK10 | Y33: 20 | Z33: 20 | AA33: 216 | AB33: 32773
A34: =A32+1 -> 25 | B34: SGHK13 | C34: VHT | D34: KV2 | E34: 1500000 | F34: 1500000 | G34: TCHK07 | I34: =VLOOKUP(B38,X:Y,2,FALSE) -> 38 | J34: 28 | K34: GGHK01 | L34: Ericsson | M34: KV2 | N34: =VLOOKUP(K34,'Chi tiết_report'!$B$123:$S$175,16,FALSE) -> 1500000 | O34: =VLOOKUP(K34,'Chi tiết_report'!$B$123:$S$175,7,FALSE) -> 80000 | P34: 60000 | Q34: =VLOOKUP(K34,'Chi tiết_report'!$B$123:$S$175,18,FALSE) -> 1690000 | R34: =VLOOKUP(K34,'Chi tiết_report'!$B$123:$Z$175,24,FALSE) -> 1495000 | S34: SSR 8020 | T34: EPG 2.17 | U34: =LOWER(CONCATENATE(K34,".",IF(L34="Ericsson","eric",IF(L34="VHT","viettel","cisco")),".zone",RIGHT(M34,1))) -> gghk01.eric.zone2 | V34: =VLOOKUP(K34,idns_weight_PCSCF!A:B,2,FALSE) -> Ericsson | X34: SGHK11 | Y34: 20 | Z34: 20 | AA34: 220 | AB34: 32773
B35: Pool KV2 | C35: VHT | E35: =SUM(E31:E34) -> 6000000 | F35: =SUM(F31:F34) -> 6000000 | I35: =VLOOKUP(B39,X:Y,2,FALSE) -> 38 | J35: 29 | K35: GGHK02 | L35: Ericsson | M35: KV2 | N35: =VLOOKUP(K35,'Chi tiết_report'!$B$123:$S$175,16,FALSE) -> 1500000 | O35: =VLOOKUP(K35,'Chi tiết_report'!$B$123:$S$175,7,FALSE) -> 80000 | P35: 60000 | Q35: =VLOOKUP(K35,'Chi tiết_report'!$B$123:$S$175,18,FALSE) -> 1690000 | R35: =VLOOKUP(K35,'Chi tiết_report'!$B$123:$Z$175,24,FALSE) -> 1495000 | S35: SSR 8020 | T35: EPG 2.17 | U35: =LOWER(CONCATENATE(K35,".",IF(L35="Ericsson","eric",IF(L35="VHT","viettel","cisco")),".zone",RIGHT(M35,1))) -> gghk02.eric.zone2 | V35: =VLOOKUP(K35,idns_weight_PCSCF!A:B,2,FALSE) -> Ericsson | X35: SGHK12 | Y35: 20 | Z35: 20 | AA35: 224 | AB35: 32773
A36: 26 | B36: SGHT07 | C36: Ericsson | D36: KV3 | E36: 2500000 | F36: 2800000 | G36: MkVIII | H36: 1.65 | I36: =VLOOKUP(B40,X:Y,2,FALSE) -> 38 | J36: 30 | K36: GGHK03 | L36: Ericsson | M36: KV2 | N36: =VLOOKUP(K36,'Chi tiết_report'!$B$123:$S$175,16,FALSE) -> 2000000 | O36: =VLOOKUP(K36,'Chi tiết_report'!$B$123:$S$175,7,FALSE) -> 80000 | P36: 80000 | Q36: =VLOOKUP(K36,'Chi tiết_report'!$B$123:$S$175,18,FALSE) -> 2148216 | R36: =VLOOKUP(K36,'Chi tiết_report'!$B$123:$Z$175,24,FALSE) -> 1755000 | S36: SSR 8020 | T36: EPG 2.17 | U36: =LOWER(CONCATENATE(K36,".",IF(L36="Ericsson","eric",IF(L36="VHT","viettel","cisco")),".zone",RIGHT(M36,1))) -> gghk03.eric.zone2 | V36: =VLOOKUP(K36,idns_weight_PCSCF!A:B,2,FALSE) -> Ericsson | X36: SGHK13 | Y36: 20 | Z36: 20 | AA36: 228 | AB36: 32773
A37: =A36+1 -> 27 | B37: SGHT08 | C37: Ericsson | D37: KV3 | E37: 2500000 | F37: 2800000 | G37: MkVIII | H37: 1.65 | I37: =VLOOKUP(B41,X:Y,2,FALSE) -> 38 | J37: 31 | K37: GGHK06 | L37: Ericsson | M37: KV2 | N37: =VLOOKUP(K37,'Chi tiết_report'!$B$123:$S$175,16,FALSE) -> 1800000 | O37: =VLOOKUP(K37,'Chi tiết_report'!$B$123:$S$175,7,FALSE) -> 110000 | P37: 90000 | Q37: =VLOOKUP(K37,'Chi tiết_report'!$B$123:$S$175,18,FALSE) -> 2015000 | R37: =VLOOKUP(K37,'Chi tiết_report'!$B$123:$Z$175,24,FALSE) -> 2535000 | S37: SSR 8020 | T37: EPG 2.17 | U37: =LOWER(CONCATENATE(K37,".",IF(L37="Ericsson","eric",IF(L37="VHT","viettel","cisco")),".zone",RIGHT(M37,1))) -> gghk06.eric.zone2 | V37: =VLOOKUP(K37,idns_weight_PCSCF!A:B,2,FALSE) -> Ericsson | X37: SGHT16 | Y37: 20 | Z37: 20 | AA37: 232 | AB37: 32774
A38: =A37+1 -> 28 | B38: SGHT09 | C38: Ericsson | D38: KV3 | E38: 3500000 | F38: 3500000 | G38: MkX | H38: 1.65 | I38: =VLOOKUP(B42,X:Y,2,FALSE) -> 38 | J38: 32 | K38: GGHK07 | L38: Ericsson | M38: KV2 | N38: =VLOOKUP(K38,'Chi tiết_report'!$B$123:$S$175,16,FALSE) -> 4000000 | O38: =VLOOKUP(K38,'Chi tiết_report'!$B$123:$S$175,7,FALSE) -> 180000 | P38: 150000 | Q38: =VLOOKUP(K38,'Chi tiết_report'!$B$123:$S$175,18,FALSE) -> 4063232 | R38: =VLOOKUP(K38,'Chi tiết_report'!$B$123:$Z$175,24,FALSE) -> 4063232 | S38: TCHK01 | U38: =LOWER(CONCATENATE(K38,".",IF(L38="Ericsson","eric",IF(L38="VHT","viettel","cisco")),".zone",RIGHT(M38,1))) -> gghk07.eric.zone2 | V38: =VLOOKUP(K38,idns_weight_PCSCF!A:B,2,FALSE) -> Ericsson | X38: SGHT17 | Y38: 20 | Z38: 20 | AA38: 236 | AB38: 32774
A39: =A38+1 -> 29 | B39: SGHT10 | C39: Ericsson | D39: KV3 | E39: 3500000 | F39: 3500000 | G39: MkX | H39: 1.65 | I39: =VLOOKUP(B43,X:Y,2,FALSE) -> 38 | J39: 33 | K39: GGHK08 | L39: Ericsson | M39: KV2 | N39: =VLOOKUP(K39,'Chi tiết_report'!$B$123:$S$175,16,FALSE) -> 4000000 | O39: =VLOOKUP(K39,'Chi tiết_report'!$B$123:$S$175,7,FALSE) -> 180000 | P39: 150000 | Q39: =VLOOKUP(K39,'Chi tiết_report'!$B$123:$S$175,18,FALSE) -> 4063232 | R39: =VLOOKUP(K39,'Chi tiết_report'!$B$123:$Z$175,24,FALSE) -> 4063232 | S39: TCHK01 | U39: =LOWER(CONCATENATE(K39,".",IF(L39="Ericsson","eric",IF(L39="VHT","viettel","cisco")),".zone",RIGHT(M39,1))) -> gghk08.eric.zone2 | V39: 125 | X39: SGHT18 | Y39: 20 | Z39: 20 | AA39: 240 | AB39: 32774
A40: =A39+1 -> 30 | B40: SGHT11 | C40: Ericsson | D40: KV3 | E40: 3400000 | F40: 3400000 | G40: MkX | H40: 1.65 | I40: =VLOOKUP(B44,X:Y,2,FALSE) -> 20 | J40: 34 | K40: GGHK09 | L40: Ericsson | M40: KV2 | N40: =VLOOKUP(K40,'Chi tiết_report'!$B$123:$S$175,16,FALSE) -> 4000000 | O40: =VLOOKUP(K40,'Chi tiết_report'!$B$123:$S$175,7,FALSE) -> 180000 | P40: 150000 | Q40: =31*131000 -> 4061000 | R40: =VLOOKUP(K40,'Chi tiết_report'!$B$123:$Z$175,24,FALSE) -> 4063232 | S40: TCHK01 | T40: EPG 2.16 | U40: =LOWER(CONCATENATE(K40,".",IF(L40="Ericsson","eric",IF(L40="VHT","viettel","cisco")),".zone",RIGHT(M40,1))) -> gghk09.eric.zone2 | V40: 125 | X40: SGPL01 | Y40: 15 | Z40: 15 | AA40: 156 | AB40: 32774
...

Sheet User_Guide
A1: TT | B1: Mục hướng dẫn | C1: File/script athena đính kèm | D1: Ghi chú
A2: 1 | B2: Hướng dẫn lấy dữ liệu NPMS đưa vào báo cáo
A3: 2 | B3: Hướng dẫn lấy dữ liệu NOCPRO đưa vào báo cáo
A4: 3 | B4: Hướng dẫn tạo báo cáo khi 1 node hoặc nhiều node thuộc cùng 1 TC hoặc CGNAT down | D4: Bao gồm cả GGSN và MME
A5: 4 | B5: Hướng dẫn lấy cấu hình tải đầu vào
B6: + Lấy rmc weight MME | C6: SELECT node, param_value FROM `eric_param` where type = 'modify_ne' and param ='rmc'
B7: + Lấy dns weight SPGW | C7: SELECT target, dnsname, weight FROM dns.include_srv where dnsname rlike '.zone' and node = 'idhk0102' ORDER BY target

Sheet Resource_GGSN_by_NPMS
E1: License (VHKT) | H1: 15/05/2023 | J1: 27/07/2024 | L1: =Input_TaiNguyenNode__GGSN_Daily!A4 -> 14/08/2024 | N1: Tỷ lệ sử dụng | P1: Tải GGSN sau khi cắt chuyển/cân tải | Y1: 0.82
